Workbook

Sheet Ocena
A1: Lp. | B1: Nazwa przypadku | C1: Zbiór | D1: Scena | E1: Kategoria scen | F1: Liczba obrazów (scenariusz) | G1: Model | H1: Rekonstrukcja GLB | I1: Obrazy źródłowe | J1: Status | K1: C – kompletność | L1: G – geometria | M1: A – artefakty | N1: D – struktura i szczegóły | O1: Q – suma | P1: Uwagi jakościowe | Q1: Kontrola | R1: Katalog źródłowy (WSL)
A2: 1 | B2: eth3d_botanical_garden_1 | C2: ETH3D | D2: botanical_garden | E2: Naturalne | F2: 1 | G2: VGGT | H2: =HYPERLINK("vggt/outputs/eth3d_botanical_garden_1/reconstruction.glb","vggt/outputs/eth3d_botanical_garden_1/reconstruction.glb") -> vggt/outputs/eth3d_botanical_garden_1/reconstruction.glb | I2: DSC_0854.JPG | J2: Oceniono | K2: 1 | L2: 3 | M2: 2 | N2: 2 | O2: =IF($J2="Niepowodzenie rekonstrukcji",0,IF(COUNT($K2:$N2)=4,SUM($K2:$N2),"")) -> 8 | Q2: =IF($J2="Niepowodzenie rekonstrukcji",IF(COUNTIF($K2:$N2,0)=4,"OK","Ustaw C, G, A, D = 0"),IF(COUNT($K2:$N2)=0,"Nieoceniony",IF(COUNT($K2:$N2)=4,"OK","Uzupełnij oceny"))) -> OK | R2: /home/kamil/dataset/eth3d/botanical_garden/images/scen_1
A3: 2 | B3: eth3d_botanical_garden_1 | C3: ETH3D | D3: botanical_garden | E3: Naturalne | F3: 1 | G3: MapAnything | H3: =HYPERLINK("mapany/outputs/eth3d_botanical_garden_1/reconstruction.glb","mapany/outputs/eth3d_botanical_garden_1/reconstruction.glb") -> mapany/outputs/eth3d_botanical_garden_1/reconstruction.glb | I3: DSC_0854.JPG | J3: Oceniono | K3: 2 | L3: 2 | M3: 1 | N3: 3 | O3: =IF($J3="Niepowodzenie rekonstrukcji",0,IF(COUNT($K3:$N3)=4,SUM($K3:$N3),"")) -> 8 | Q3: =IF($J3="Niepowodzenie rekonstrukcji",IF(COUNTIF($K3:$N3,0)=4,"OK","Ustaw C, G, A, D = 0"),IF(COUNT($K3:$N3)=0,"Nieoceniony",IF(COUNT($K3:$N3)=4,"OK","Uzupełnij oceny"))) -> OK | R3: /home/kamil/dataset/eth3d/botanical_garden/images/scen_1
A4: 3 | B4: eth3d_botanical_garden_2 | C4: ETH3D | D4: botanical_garden | E4: Naturalne | F4: 2 | G4: VGGT | H4: =HYPERLINK("vggt/outputs/eth3d_botanical_garden_2/reconstruction.glb","vggt/outputs/eth3d_botanical_garden_2/reconstruction.glb") -> vggt/outputs/eth3d_botanical_garden_2/reconstruction.glb | I4: DSC_0852.JPG DSC_0854.JPG | J4: Oceniono | K4: 2 | L4: 2 | M4: 2 | N4: 1 | O4: =IF($J4="Niepowodzenie rekonstrukcji",0,IF(COUNT($K4:$N4)=4,SUM($K4:$N4),"")) -> 7 | Q4: =IF($J4="Niepowodzenie rekonstrukcji",IF(COUNTIF($K4:$N4,0)=4,"OK","Ustaw C, G, A, D = 0"),IF(COUNT($K4:$N4)=0,"Nieoceniony",IF(COUNT($K4:$N4)=4,"OK","Uzupełnij oceny"))) -> OK | R4: /home/kamil/dataset/eth3d/botanical_garden/images/scen_2
A5: 4 | B5: eth3d_botanical_garden_2 | C5: ETH3D | D5: botanical_garden | E5: Naturalne | F5: 2 | G5: MASt3R | H5: =HYPERLINK("mast3r/outputs/eth3d_botanical_garden_2/reconstruction.glb","mast3r/outputs/eth3d_botanical_garden_2/reconstruction.glb") -> mast3r/outputs/eth3d_botanical_garden_2/reconstruction.glb | I5: DSC_0852.JPG DSC_0854.JPG | J5: Oceniono | K5: 1 | L5: 2 | M5: 2 | N5: 1 | O5: =IF($J5="Niepowodzenie rekonstrukcji",0,IF(COUNT($K5:$N5)=4,SUM($K5:$N5),"")) -> 6 | Q5: =IF($J5="Niepowodzenie rekonstrukcji",IF(COUNTIF($K5:$N5,0)=4,"OK","Ustaw C, G, A, D = 0"),IF(COUNT($K5:$N5)=0,"Nieoceniony",IF(COUNT($K5:$N5)=4,"OK","Uzupełnij oceny"))) -> OK | R5: /home/kamil/dataset/eth3d/botanical_garden/images/scen_2
A6: 5 | B6: eth3d_botanical_garden_2 | C6: ETH3D | D6: botanical_garden | E6: Naturalne | F6: 2 | G6: MapAnything | H6: =HYPERLINK("mapany/outputs/eth3d_botanical_garden_2/reconstruction.glb","mapany/outputs/eth3d_botanical_garden_2/reconstruction.glb") -> mapany/outputs/eth3d_botanical_garden_2/reconstruction.glb | I6: DSC_0852.JPG DSC_0854.JPG | J6: Oceniono | K6: 3 | L6: 1 | M6: 1 | N6: 2 | O6: =IF($J6="Niepowodzenie rekonstrukcji",0,IF(COUNT($K6:$N6)=4,SUM($K6:$N6),"")) -> 7 | Q6: =IF($J6="Niepowodzenie rekonstrukcji",IF(COUNTIF($K6:$N6,0)=4,"OK","Ustaw C, G, A, D = 0"),IF(COUNT($K6:$N6)=0,"Nieoceniony",IF(COUNT($K6:$N6)=4,"OK","Uzupełnij oceny"))) -> OK | R6: /home/kamil/dataset/eth3d/botanical_garden/images/scen_2
A7: 6 | B7: eth3d_botanical_garden_3 | C7: ETH3D | D7: botanical_garden | E7: Naturalne | F7: 4 | G7: VGGT | H7: =HYPERLINK("vggt/outputs/eth3d_botanical_garden_3/reconstruction.glb","vggt/outputs/eth3d_botanical_garden_3/reconstruction.glb") -> vggt/outputs/eth3d_botanical_garden_3/reconstruction.glb | I7: DSC_0850.JPG DSC_0852.JPG DSC_0854.JPG DSC_0857.JPG | J7: Oceniono | K7: 1 | L7: 2 | M7: 2 | N7: 1 | O7: =IF($J7="Niepowodzenie rekonstrukcji",0,IF(COUNT($K7:$N7)=4,SUM($K7:$N7),"")) -> 6 | Q7: =IF($J7="Niepowodzenie rekonstrukcji",IF(COUNTIF($K7:$N7,0)=4,"OK","Ustaw C, G, A, D = 0"),IF(COUNT($K7:$N7)=0,"Nieoceniony",IF(COUNT($K7:$N7)=4,"OK","Uzupełnij oceny"))) -> OK | R7: /home/kamil/dataset/eth3d/botanical_garden/images/scen_3
A8: 7 | B8: eth3d_botanical_garden_3 | C8: ETH3D | D8: botanical_garden | E8: Naturalne | F8: 4 | G8: MASt3R | H8: =HYPERLINK("mast3r/outputs/eth3d_botanical_garden_3/reconstruction.glb","mast3r/outputs/eth3d_botanical_garden_3/reconstruction.glb") -> mast3r/outputs/eth3d_botanical_garden_3/reconstruction.glb | I8: DSC_0850.JPG DSC_0852.JPG DSC_0854.JPG DSC_0857.JPG | J8: Oceniono | K8: 2 | L8: 2 | M8: 2 | N8: 1 | O8: =IF($J8="Niepowodzenie rekonstrukcji",0,IF(COUNT($K8:$N8)=4,SUM($K8:$N8),"")) -> 7 | Q8: =IF($J8="Niepowodzenie rekonstrukcji",IF(COUNTIF($K8:$N8,0)=4,"OK","Ustaw C, G, A, D = 0"),IF(COUNT($K8:$N8)=0,"Nieoceniony",IF(COUNT($K8:$N8)=4,"OK","Uzupełnij oceny"))) -> OK | R8: /home/kamil/dataset/eth3d/botanical_garden/images/scen_3
A9: 8 | B9: eth3d_botanical_garden_3 | C9: ETH3D | D9: botanical_garden | E9: Naturalne | F9: 4 | G9: MapAnything | H9: =HYPERLINK("mapany/outputs/eth3d_botanical_garden_3/reconstruction.glb","mapany/outputs/eth3d_botanical_garden_3/reconstruction.glb") -> mapany/outputs/eth3d_botanical_garden_3/reconstruction.glb | I9: DSC_0850.JPG DSC_0852.JPG DSC_0854.JPG DSC_0857.JPG | J9: Oceniono | K9: 3 | L9: 1 | M9: 1 | N9: 2 | O9: =IF($J9="Niepowodzenie rekonstrukcji",0,IF(COUNT($K9:$N9)=4,SUM($K9:$N9),"")) -> 7 | Q9: =IF($J9="Niepowodzenie rekonstrukcji",IF(COUNTIF($K9:$N9,0)=4,"OK","Ustaw C, G, A, D = 0"),IF(COUNT($K9:$N9)=0,"Nieoceniony",IF(COUNT($K9:$N9)=4,"OK","Uzupełnij oceny"))) -> OK | R9: /home/kamil/dataset/eth3d/botanical_garden/images/scen_3
A10: 9 | B10: eth3d_botanical_garden_4 | C10: ETH3D | D10: botanical_garden | E10: Naturalne | F10: 8 | G10: VGGT | H10: =HYPERLINK("vggt/outputs/eth3d_botanical_garden_4/reconstruction.glb","vggt/outputs/eth3d_botanical_garden_4/reconstruction.glb") -> vggt/outputs/eth3d_botanical_garden_4/reconstruction.glb | I10: DSC_0844.JPG DSC_0846.JPG DSC_0848.JPG DSC_0850.JPG DSC_0852.JPG DSC_0854.JPG DSC_0856.JPG DSC_0857.JPG | J10: Oceniono | K10: 1 | L10: 2 | M10: 2 | N10: 2 | O10: =IF($J10="Niepowodzenie rekonstrukcji",0,IF(COUNT($K10:$N10)=4,SUM($K10:$N10),"")) -> 7 | Q10: =IF($J10="Niepowodzenie rekonstrukcji",IF(COUNTIF($K10:$N10,0)=4,"OK","Ustaw C, G, A, D = 0"),IF(COUNT($K10:$N10)=0,"Nieoceniony",IF(COUNT($K10:$N10)=4,"OK","Uzupełnij oceny"))) -> OK | R10: /home/kamil/dataset/eth3d/botanical_garden/images/scen_4
A11: 10 | B11: eth3d_botanical_garden_4 | C11: ETH3D | D11: botanical_garden | E11: Naturalne | F11: 8 | G11: MASt3R | H11: =HYPERLINK("mast3r/outputs/eth3d_botanical_garden_4/reconstruction.glb","mast3r/outputs/eth3d_botanical_garden_4/reconstruction.glb") -> mast3r/outputs/eth3d_botanical_garden_4/reconstruction.glb | I11: DSC_0844.JPG DSC_0846.JPG DSC_0848.JPG DSC_0850.JPG DSC_0852.JPG DSC_0854.JPG DSC_0856.JPG DSC_0857.JPG | J11: Oceniono | K11: 0 | L11: 0 | M11: 0 | N11: 1 | O11: =IF($J11="Niepowodzenie rekonstrukcji",0,IF(COUNT($K11:$N11)=4,SUM($K11:$N11),"")) -> 1 | Q11: =IF($J11="Niepowodzenie rekonstrukcji",IF(COUNTIF($K11:$N11,0)=4,"OK","Ustaw C, G, A, D = 0"),IF(COUNT($K11:$N11)=0,"Nieoceniony",IF(COUNT($K11:$N11)=4,"OK","Uzupełnij oceny"))) -> OK | R11: /home/kamil/dataset/eth3d/botanical_garden/images/scen_4
A12: 11 | B12: eth3d_botanical_garden_4 | C12: ETH3D | D12: botanical_garden | E12: Naturalne | F12: 8 | G12: MapAnything | H12: =HYPERLINK("mapany/outputs/eth3d_botanical_garden_4/reconstruction.glb","mapany/outputs/eth3d_botanical_garden_4/reconstruction.glb") -> mapany/outputs/eth3d_botanical_garden_4/reconstruction.glb | I12: DSC_0844.JPG DSC_0846.JPG DSC_0848.JPG DSC_0850.JPG DSC_0852.JPG DSC_0854.JPG DSC_0856.JPG DSC_0857.JPG | J12: Oceniono | K12: 2 | L12: 1 | M12: 1 | N12: 2 | O12: =IF($J12="Niepowodzenie rekonstrukcji",0,IF(COUNT($K12:$N12)=4,SUM($K12:$N12),"")) -> 6 | Q12: =IF($J12="Niepowodzenie rekonstrukcji",IF(COUNTIF($K12:$N12,0)=4,"OK","Ustaw C, G, A, D = 0"),IF(COUNT($K12:$N12)=0,"Nieoceniony",IF(COUNT($K12:$N12)=4,"OK","Uzupełnij oceny"))) -> OK | R12: /home/kamil/dataset/eth3d/botanical_garden/images/scen_4
A13: 12 | B13: eth3d_boulders_scen_1 | C13: ETH3D | D13: boulders | E13: Zewnętrzne | F13: 1 | G13: VGGT | H13: =HYPERLINK("vggt/outputs/eth3d_boulders_scen_1/reconstruction.glb","vggt/outputs/eth3d_boulders_scen_1/reconstruction.glb") -> vggt/outputs/eth3d_boulders_scen_1/reconstruction.glb | I13: DSC_0821.JPG | J13: Oceniono | K13: 3 | L13: 1 | M13: 1 | N13: 2 | O13: =IF($J13="Niepowodzenie rekonstrukcji",0,IF(COUNT($K13:$N13)=4,SUM($K13:$N13),"")) -> 7 | Q13: =IF($J13="Niepowodzenie rekonstrukcji",IF(COUNTIF($K13:$N13,0)=4,"OK","Ustaw C, G, A, D = 0"),IF(COUNT($K13:$N13)=0,"Nieoceniony",IF(COUNT($K13:$N13)=4,"OK","Uzupełnij oceny"))) -> OK | R13: /home/kamil/dataset/eth3d/boulders/images/scen_1
A14: 13 | B14: eth3d_boulders_scen_1 | C14: ETH3D | D14: boulders | E14: Zewnętrzne | F14: 1 | G14: MapAnything | H14: =HYPERLINK("mapany/outputs/eth3d_boulders_scen_1/reconstruction.glb","mapany/outputs/eth3d_boulders_scen_1/reconstruction.glb") -> mapany/outputs/eth3d_boulders_scen_1/reconstruction.glb | I14: DSC_0821.JPG | J14: Oceniono | K14: 2 | L14: 1 | M14: 1 | N14: 1 | O14: =IF($J14="Niepowodzenie rekonstrukcji",0,IF(COUNT($K14:$N14)=4,SUM($K14:$N14),"")) -> 5 | Q14: =IF($J14="Niepowodzenie rekonstrukcji",IF(COUNTIF($K14:$N14,0)=4,"OK","Ustaw C, G, A, D = 0"),IF(COUNT($K14:$N14)=0,"Nieoceniony",IF(COUNT($K14:$N14)=4,"OK","Uzupełnij oceny"))) -> OK | R14: /home/kamil/dataset/eth3d/boulders/images/scen_1
A15: 14 | B15: eth3d_boulders_scen_2 | C15: ETH3D | D15: boulders | E15: Zewnętrzne | F15: 2 | G15: VGGT | H15: =HYPERLINK("vggt/outputs/eth3d_boulders_scen_2/reconstruction.glb","vggt/outputs/eth3d_boulders_scen_2/reconstruction.glb") -> vggt/outputs/eth3d_boulders_scen_2/reconstruction.glb | I15: DSC_0819.JPG DSC_0821.JPG | J15: Oceniono | K15: 3 | L15: 1 | M15: 1 | N15: 2 | O15: =IF($J15="Niepowodzenie rekonstrukcji",0,IF(COUNT($K15:$N15)=4,SUM($K15:$N15),"")) -> 7 | Q15: =IF($J15="Niepowodzenie rekonstrukcji",IF(COUNTIF($K15:$N15,0)=4,"OK","Ustaw C, G, A, D = 0"),IF(COUNT($K15:$N15)=0,"Nieoceniony",IF(COUNT($K15:$N15)=4,"OK","Uzupełnij oceny"))) -> OK | R15: /home/kamil/dataset/eth3d/boulders/images/scen_2
A16: 15 | B16: eth3d_boulders_scen_2 | C16: ETH3D | D16: boulders | E16: Zewnętrzne | F16: 2 | G16: MASt3R | H16: =HYPERLINK("mast3r/outputs/eth3d_boulders_scen_2/reconstruction.glb","mast3r/outputs/eth3d_boulders_scen_2/reconstruction.glb") -> mast3r/outputs/eth3d_boulders_scen_2/reconstruction.glb | I16: DSC_0819.JPG DSC_0821.JPG | J16: Oceniono | K16: 1 | L16: 3 | M16: 2 | N16: 1 | O16: =IF($J16="Niepowodzenie rekonstrukcji",0,IF(COUNT($K16:$N16)=4,SUM($K16:$N16),"")) -> 7 | Q16: =IF($J16="Niepowodzenie rekonstrukcji",IF(COUNTIF($K16:$N16,0)=4,"OK","Ustaw C, G, A, D = 0"),IF(COUNT($K16:$N16)=0,"Nieoceniony",IF(COUNT($K16:$N16)=4,"OK","Uzupełnij oceny"))) -> OK | R16: /home/kamil/dataset/eth3d/boulders/images/scen_2
A17: 16 | B17: eth3d_boulders_scen_2 | C17: ETH3D | D17: boulders | E17: Zewnętrzne | F17: 2 | G17: MapAnything | H17: =HYPERLINK("mapany/outputs/eth3d_boulders_scen_2/reconstruction.glb","mapany/outputs/eth3d_boulders_scen_2/reconstruction.glb") -> mapany/outputs/eth3d_boulders_scen_2/reconstruction.glb | I17: DSC_0819.JPG DSC_0821.JPG | J17: Oceniono | K17: 2 | L17: 2 | M17: 2 | N17: 2 | O17: =IF($J17="Niepowodzenie rekonstrukcji",0,IF(COUNT($K17:$N17)=4,SUM($K17:$N17),"")) -> 8 | Q17: =IF($J17="Niepowodzenie rekonstrukcji",IF(COUNTIF($K17:$N17,0)=4,"OK","Ustaw C, G, A, D = 0"),IF(COUNT($K17:$N17)=0,"Nieoceniony",IF(COUNT($K17:$N17)=4,"OK","Uzupełnij oceny"))) -> OK | R17: /home/kamil/dataset/eth3d/boulders/images/scen_2
A18: 17 | B18: eth3d_boulders_scen_3 | C18: ETH3D | D18: boulders | E18: Zewnętrzne | F18: 4 | G18: VGGT | H18: =HYPERLINK("vggt/outputs/eth3d_boulders_scen_3/reconstruction.glb","vggt/outputs/eth3d_boulders_scen_3/reconstruction.glb") -> vggt/outputs/eth3d_boulders_scen_3/reconstruction.glb | I18: DSC_0817.JPG DSC_0819.JPG DSC_0821.JPG DSC_0823.JPG | J18: Oceniono | K18: 2 | L18: 2 | M18: 2 | N18: 2 | O18: =IF($J18="Niepowodzenie rekonstrukcji",0,IF(COUNT($K18:$N18)=4,SUM($K18:$N18),"")) -> 8 | Q18: =IF($J18="Niepowodzenie rekonstrukcji",IF(COUNTIF($K18:$N18,0)=4,"OK","Ustaw C, G, A, D = 0"),IF(COUNT($K18:$N18)=0,"Nieoceniony",IF(COUNT($K18:$N18)=4,"OK","Uzupełnij oceny"))) -> OK | R18: /home/kamil/dataset/eth3d/boulders/images/scen_3
A19: 18 | B19: eth3d_boulders_scen_3 | C19: ETH3D | D19: boulders | E19: Zewnętrzne | F19: 4 | G19: MASt3R | H19: =HYPERLINK("mast3r/outputs/eth3d_boulders_scen_3/reconstruction.glb","mast3r/outputs/eth3d_boulders_scen_3/reconstruction.glb") -> mast3r/outputs/eth3d_boulders_scen_3/reconstruction.glb | I19: DSC_0817.JPG DSC_0819.JPG DSC_0821.JPG DSC_0823.JPG | J19: Oceniono | K19: 1 | L19: 2 | M19: 2 | N19: 1 | O19: =IF($J19="Niepowodzenie rekonstrukcji",0,IF(COUNT($K19:$N19)=4,SUM($K19:$N19),"")) -> 6 | Q19: =IF($J19="Niepowodzenie rekonstrukcji",IF(COUNTIF($K19:$N19,0)=4,"OK","Ustaw C, G, A, D = 0"),IF(COUNT($K19:$N19)=0,"Nieoceniony",IF(COUNT($K19:$N19)=4,"OK","Uzupełnij oceny"))) -> OK | R19: /home/kamil/dataset/eth3d/boulders/images/scen_3
A20: 19 | B20: eth3d_boulders_scen_3 | C20: ETH3D | D20: boulders | E20: Zewnętrzne | F20: 4 | G20: MapAnything | H20: =HYPERLINK("mapany/outputs/eth3d_boulders_scen_3/reconstruction.glb","mapany/outputs/eth3d_boulders_scen_3/reconstruction.glb") -> mapany/outputs/eth3d_boulders_scen_3/reconstruction.glb | I20: DSC_0817.JPG DSC_0819.JPG DSC_0821.JPG DSC_0823.JPG | J20: Oceniono | K20: 3 | L20: 2 | M20: 2 | N20: 2 | O20: =IF($J20="Niepowodzenie rekonstrukcji",0,IF(COUNT($K20:$N20)=4,SUM($K20:$N20),"")) -> 9 | Q20: =IF($J20="Niepowodzenie rekonstrukcji",IF(COUNTIF($K20:$N20,0)=4,"OK","Ustaw C, G, A, D = 0"),IF(COUNT($K20:$N20)=0,"Nieoceniony",IF(COUNT($K20:$N20)=4,"OK","Uzupełnij oceny"))) -> OK | R20: /home/kamil/dataset/eth3d/boulders/images/scen_3
A21: 20 | B21: eth3d_boulders_scen_4 | C21: ETH3D | D21: boulders | E21: Zewnętrzne | F21: 8 | G21: VGGT | H21: =HYPERLINK("vggt/outputs/eth3d_boulders_scen_4/reconstruction.glb","vggt/outputs/eth3d_boulders_scen_4/reconstruction.glb") -> vggt/outputs/eth3d_boulders_scen_4/reconstruction.glb | I21: DSC_0817.JPG DSC_0818.JPG DSC_0819.JPG DSC_0820.JPG DSC_0821.JPG DSC_0822.JPG DSC_0823.JPG DSC_0824.JPG | J21: Oceniono | K21: 2 | L21: 2 | M21: 2 | N21: 2 | O21: =IF($J21="Niepowodzenie rekonstrukcji",0,IF(COUNT($K21:$N21)=4,SUM($K21:$N21),"")) -> 8 | Q21: =IF($J21="Niepowodzenie rekonstrukcji",IF(COUNTIF($K21:$N21,0)=4,"OK","Ustaw C, G, A, D = 0"),IF(COUNT($K21:$N21)=0,"Nieoceniony",IF(COUNT($K21:$N21)=4,"OK","Uzupełnij oceny"))) -> OK | R21: /home/kamil/dataset/eth3d/boulders/images/scen_4
A22: 21 | B22: eth3d_boulders_scen_4 | C22: ETH3D | D22: boulders | E22: Zewnętrzne | F22: 8 | G22: MASt3R | H22: =HYPERLINK("mast3r/outputs/eth3d_boulders_scen_4/reconstruction.glb","mast3r/outputs/eth3d_boulders_scen_4/reconstruction.glb") -> mast3r/outputs/eth3d_boulders_scen_4/reconstruction.glb | I22: DSC_0817.JPG DSC_0818.JPG DSC_0819.JPG DSC_0820.JPG DSC_0821.JPG DSC_0822.JPG DSC_0823.JPG DSC_0824.JPG | J22: Oceniono | K22: 1 | L22: 2 | M22: 1 | N22: 1 | O22: =IF($J22="Niepowodzenie rekonstrukcji",0,IF(COUNT($K22:$N22)=4,SUM($K22:$N22),"")) -> 5 | Q22: =IF($J22="Niepowodzenie rekonstrukcji",IF(COUNTIF($K22:$N22,0)=4,"OK","Ustaw C, G, A, D = 0"),IF(COUNT($K22:$N22)=0,"Nieoceniony",IF(COUNT($K22:$N22)=4,"OK","Uzupełnij oceny"))) -> OK | R22: /home/kamil/dataset/eth3d/boulders/images/scen_4
A23: 22 | B23: eth3d_boulders_scen_4 | C23: ETH3D | D23: boulders | E23: Zewnętrzne | F23: 8 | G23: MapAnything | H23: =HYPERLINK("mapany/outputs/eth3d_boulders_scen_4/reconstruction.glb","mapany/outputs/eth3d_boulders_scen_4/reconstruction.glb") -> mapany/outputs/eth3d_boulders_scen_4/reconstruction.glb | I23: DSC_0817.JPG DSC_0818.JPG DSC_0819.JPG DSC_0820.JPG DSC_0821.JPG DSC_0822.JPG DSC_0823.JPG DSC_0824.JPG | J23: Oceniono | K23: 3 | L23: 2 | M23: 2 | N23: 2 | O23: =IF($J23="Niepowodzenie rekonstrukcji",0,IF(COUNT($K23:$N23)=4,SUM($K23:$N23),"")) -> 9 | Q23: =IF($J23="Niepowodzenie rekonstrukcji",IF(COUNTIF($K23:$N23,0)=4,"OK","Ustaw C, G, A, D = 0"),IF(COUNT($K23:$N23)=0,"Nieoceniony",IF(COUNT($K23:$N23)=4,"OK","Uzupełnij oceny"))) -> OK | R23: /home/kamil/dataset/eth3d/boulders/images/scen_4
A24: 23 | B24: eth3d_bridge_scen_1 | C24: ETH3D | D24: bridge | E24: Wewnętrzne | F24: 1 | G24: VGGT | H24: =HYPERLINK("vggt/outputs/eth3d_bridge_scen_1/reconstruction.glb","vggt/outputs/eth3d_bridge_scen_1/reconstruction.glb") -> vggt/outputs/eth3d_bridge_scen_1/reconstruction.glb | I24: DSC_1256.JPG | J24: Oceniono | K24: 1 | L24: 3 | M24: 3 | N24: 1 | O24: =IF($J24="Niepowodzenie rekonstrukcji",0,IF(COUNT($K24:$N24)=4,SUM($K24:$N24),"")) -> 8 | Q24: =IF($J24="Niepowodzenie rekonstrukcji",IF(COUNTIF($K24:$N24,0)=4,"OK","Ustaw C, G, A, D = 0"),IF(COUNT($K24:$N24)=0,"Nieoceniony",IF(COUNT($K24:$N24)=4,"OK","Uzupełnij oceny"))) -> OK | R24: /home/kamil/dataset/eth3d/bridge/images/scen_1
A25: 24 | B25: eth3d_bridge_scen_1 | C25: ETH3D | D25: bridge | E25: Wewnętrzne | F25: 1 | G25: MapAnything | H25: =HYPERLINK("mapany/outputs/eth3d_bridge_scen_1/reconstruction.glb","mapany/outputs/eth3d_bridge_scen_1/reconstruction.glb") -> mapany/outputs/eth3d_bridge_scen_1/reconstruction.glb | I25: DSC_1256.JPG | J25: Oceniono | K25: 2 | L25: 2 | M25: 2 | N25: 2 | O25: =IF($J25="Niepowodzenie rekonstrukcji",0,IF(COUNT($K25:$N25)=4,SUM($K25:$N25),"")) -> 8 | Q25: =IF($J25="Niepowodzenie rekonstrukcji",IF(COUNTIF($K25:$N25,0)=4,"OK","Ustaw C, G, A, D = 0"),IF(COUNT($K25:$N25)=0,"Nieoceniony",IF(COUNT($K25:$N25)=4,"OK","Uzupełnij oceny"))) -> OK | R25: /home/kamil/dataset/eth3d/bridge/images/scen_1
A26: 25 | B26: eth3d_bridge_scen_2 | C26: ETH3D | D26: bridge | E26: Wewnętrzne | F26: 2 | G26: VGGT | H26: =HYPERLINK("vggt/outputs/eth3d_bridge_scen_2/reconstruction.glb","vggt/outputs/eth3d_bridge_scen_2/reconstruction.glb") -> vggt/outputs/eth3d_bridge_scen_2/reconstruction.glb | I26: DSC_1256.JPG DSC_1258.JPG | J26: Oceniono | K26: 1 | L26: 3 | M26: 3 | N26: 1 | O26: =IF($J26="Niepowodzenie rekonstrukcji",0,IF(COUNT($K26:$N26)=4,SUM($K26:$N26),"")) -> 8 | Q26: =IF($J26="Niepowodzenie rekonstrukcji",IF(COUNTIF($K26:$N26,0)=4,"OK","Ustaw C, G, A, D = 0"),IF(COUNT($K26:$N26)=0,"Nieoceniony",IF(COUNT($K26:$N26)=4,"OK","Uzupełnij oceny"))) -> OK | R26: /home/kamil/dataset/eth3d/bridge/images/scen_2
A27: 26 | B27: eth3d_bridge_scen_2 | C27: ETH3D | D27: bridge | E27: Wewnętrzne | F27: 2 | G27: MASt3R | H27: =HYPERLINK("mast3r/outputs/eth3d_bridge_scen_2/reconstruction.glb","mast3r/outputs/eth3d_bridge_scen_2/reconstruction.glb") -> mast3r/outputs/eth3d_bridge_scen_2/reconstruction.glb | I27: DSC_1256.JPG DSC_1258.JPG | J27: Oceniono | K27: 2 | L27: 3 | M27: 2 | N27: 2 | O27: =IF($J27="Niepowodzenie rekonstrukcji",0,IF(COUNT($K27:$N27)=4,SUM($K27:$N27),"")) -> 9 | Q27: =IF($J27="Niepowodzenie rekonstrukcji",IF(COUNTIF($K27:$N27,0)=4,"OK","Ustaw C, G, A, D = 0"),IF(COUNT($K27:$N27)=0,"Nieoceniony",IF(COUNT($K27:$N27)=4,"OK","Uzupełnij oceny"))) -> OK | R27: /home/kamil/dataset/eth3d/bridge/images/scen_2
A28: 27 | B28: eth3d_bridge_scen_2 | C28: ETH3D | D28: bridge | E28: Wewnętrzne | F28: 2 | G28: MapAnything | H28: =HYPERLINK("mapany/outputs/eth3d_bridge_scen_2/reconstruction.glb","mapany/outputs/eth3d_bridge_scen_2/reconstruction.glb") -> mapany/outputs/eth3d_bridge_scen_2/reconstruction.glb | I28: DSC_1256.JPG DSC_1258.JPG | J28: Oceniono | K28: 3 | L28: 2 | M28: 2 | N28: 2 | O28: =IF($J28="Niepowodzenie rekonstrukcji",0,IF(COUNT($K28:$N28)=4,SUM($K28:$N28),"")) -> 9 | Q28: =IF($J28="Niepowodzenie rekonstrukcji",IF(COUNTIF($K28:$N28,0)=4,"OK","Ustaw C, G, A, D = 0"),IF(COUNT($K28:$N28)=0,"Nieoceniony",IF(COUNT($K28:$N28)=4,"OK","Uzupełnij oceny"))) -> OK | R28: /home/kamil/dataset/eth3d/bridge/images/scen_2
A29: 28 | B29: eth3d_bridge_scen_3 | C29: ETH3D | D29: bridge | E29: Wewnętrzne | F29: 4 | G29: VGGT | H29: =HYPERLINK("vggt/outputs/eth3d_bridge_scen_3/reconstruction.glb","vggt/outputs/eth3d_bridge_scen_3/reconstruction.glb") -> vggt/outputs/eth3d_bridge_scen_3/reconstruction.glb | I29: DSC_1256.JPG DSC_1258.JPG DSC_1260.JPG DSC_1262.JPG | J29: Oceniono | K29: 1 | L29: 2 | M29: 2 | N29: 1 | O29: =IF($J29="Niepowodzenie rekonstrukcji",0,IF(COUNT($K29:$N29)=4,SUM($K29:$N29),"")) -> 6 | Q29: =IF($J29="Niepowodzenie rekonstrukcji",IF(COUNTIF($K29:$N29,0)=4,"OK","Ustaw C, G, A, D = 0"),IF(COUNT($K29:$N29)=0,"Nieoceniony",IF(COUNT($K29:$N29)=4,"OK","Uzupełnij oceny"))) -> OK | R29: /home/kamil/dataset/eth3d/bridge/images/scen_3
A30: 29 | B30: eth3d_bridge_scen_3 | C30: ETH3D | D30: bridge | E30: Wewnętrzne | F30: 4 | G30: MASt3R | H30: =HYPERLINK("mast3r/outputs/eth3d_bridge_scen_3/reconstruction.glb","mast3r/outputs/eth3d_bridge_scen_3/reconstruction.glb") -> mast3r/outputs/eth3d_bridge_scen_3/reconstruction.glb | I30: DSC_1256.JPG DSC_1258.JPG DSC_1260.JPG DSC_1262.JPG | J30: Oceniono | K30: 2 | L30: 2 | M30: 1 | N30: 2 | O30: =IF($J30="Niepowodzenie rekonstrukcji",0,IF(COUNT($K30:$N30)=4,SUM($K30:$N30),"")) -> 7 | Q30: =IF($J30="Niepowodzenie rekonstrukcji",IF(COUNTIF($K30:$N30,0)=4,"OK","Ustaw C, G, A, D = 0"),IF(COUNT($K30:$N30)=0,"Nieoceniony",IF(COUNT($K30:$N30)=4,"OK","Uzupełnij oceny"))) -> OK | R30: /home/kamil/dataset/eth3d/bridge/images/scen_3
A31: 30 | B31: eth3d_bridge_scen_3 | C31: ETH3D | D31: bridge | E31: Wewnętrzne | F31: 4 | G31: MapAnything | H31: =HYPERLINK("mapany/outputs/eth3d_bridge_scen_3/reconstruction.glb","mapany/outputs/eth3d_bridge_scen_3/reconstruction.glb") -> mapany/outputs/eth3d_bridge_scen_3/reconstruction.glb | I31: DSC_1256.JPG DSC_1258.JPG DSC_1260.JPG DSC_1262.JPG | J31: Oceniono | K31: 3 | L31: 2 | M31: 3 | N31: 3 | O31: =IF($J31="Niepowodzenie rekonstrukcji",0,IF(COUNT($K31:$N31)=4,SUM($K31:$N31),"")) -> 11 | Q31: =IF($J31="Niepowodzenie rekonstrukcji",IF(COUNTIF($K31:$N31,0)=4,"OK","Ustaw C, G, A, D = 0"),IF(COUNT($K31:$N31)=0,"Nieoceniony",IF(COUNT($K31:$N31)=4,"OK","Uzupełnij oceny"))) -> OK | R31: /home/kamil/dataset/eth3d/bridge/images/scen_3
A32: 31 | B32: eth3d_bridge_scen_4 | C32: ETH3D | D32: bridge | E32: Wewnętrzne | F32: 8 | G32: VGGT | H32: =HYPERLINK("vggt/outputs/eth3d_bridge_scen_4/reconstruction.glb","vggt/outputs/eth3d_bridge_scen_4/reconstruction.glb") -> vggt/outputs/eth3d_bridge_scen_4/reconstruction.glb | I32: DSC_1249.JPG DSC_1256.JPG DSC_1258.JPG DSC_1260.JPG DSC_1262.JPG DSC_1265.JPG DSC_1267.JPG DSC_1269.JPG | J32: Oceniono | K32: 1 | L32: 0 | M32: 2 | N32: 1 | O32: =IF($J32="Niepowodzenie rekonstrukcji",0,IF(COUNT($K32:$N32)=4,SUM($K32:$N32),"")) -> 4 | Q32: =IF($J32="Niepowodzenie rekonstrukcji",IF(COUNTIF($K32:$N32,0)=4,"OK","Ustaw C, G, A, D = 0"),IF(COUNT($K32:$N32)=0,"Nieoceniony",IF(COUNT($K32:$N32)=4,"OK","Uzupełnij oceny"))) -> OK | R32: /home/kamil/dataset/eth3d/bridge/images/scen_4
A33: 32 | B33: eth3d_bridge_scen_4 | C33: ETH3D | D33: bridge | E33: Wewnętrzne | F33: 8 | G33: MASt3R | H33: =HYPERLINK("mast3r/outputs/eth3d_bridge_scen_4/reconstruction.glb","mast3r/outputs/eth3d_bridge_scen_4/reconstruction.glb") -> mast3r/outputs/eth3d_bridge_scen_4/reconstruction.glb | I33: DSC_1249.JPG DSC_1256.JPG DSC_1258.JPG DSC_1260.JPG DSC_1262.JPG DSC_1265.JPG DSC_1267.JPG DSC_1269.JPG | J33: Oceniono | K33: 1 | L33: 0 | M33: 0 | N33: 1 | O33: =IF($J33="Niepowodzenie rekonstrukcji",0,IF(COUNT($K33:$N33)=4,SUM($K33:$N33),"")) -> 2 | Q33: =IF($J33="Niepowodzenie rekonstrukcji",IF(COUNTIF($K33:$N33,0)=4,"OK","Ustaw C, G, A, D = 0"),IF(COUNT($K33:$N33)=0,"Nieoceniony",IF(COUNT($K33:$N33)=4,"OK","Uzupełnij oceny"))) -> OK | R33: /home/kamil/dataset/eth3d/bridge/images/scen_4
A34: 33 | B34: eth3d_bridge_scen_4 | C34: ETH3D | D34: bridge | E34: Wewnętrzne | F34: 8 | G34: MapAnything | H34: =HYPERLINK("mapany/outputs/eth3d_bridge_scen_4/reconstruction.glb","mapany/outputs/eth3d_bridge_scen_4/reconstruction.glb") -> mapany/outputs/eth3d_bridge_scen_4/reconstruction.glb | I34: DSC_1249.JPG DSC_1256.JPG DSC_1258.JPG DSC_1260.JPG DSC_1262.JPG DSC_1265.JPG DSC_1267.JPG DSC_1269.JPG | J34: Oceniono | K34: 2 | L34: 2 | M34: 1 | N34: 2 | O34: =IF($J34="Niepowodzenie rekonstrukcji",0,IF(COUNT($K34:$N34)=4,SUM($K34:$N34),"")) -> 7 | Q34: =IF($J34="Niepowodzenie rekonstrukcji",IF(COUNTIF($K34:$N34,0)=4,"OK","Ustaw C, G, A, D = 0"),IF(COUNT($K34:$N34)=0,"Nieoceniony",IF(COUNT($K34:$N34)=4,"OK","Uzupełnij oceny"))) -> OK | R34: /home/kamil/dataset/eth3d/bridge/images/scen_4
A35: 34 | B35: custom_bush_1_scen_1 | C35: Custom | D35: bush_1 | E35: Naturalne | F35: 1 | G35: VGGT | H35: =HYPERLINK("vggt/outputs/custom_bush_1_scen_1/reconstruction.glb","vggt/outputs/custom_bush_1_scen_1/reconstruction.glb") -> vggt/outputs/custom_bush_1_scen_1/reconstruction.glb | I35: IMG_9126.jpg | J35: Oceniono | K35: 1 | L35: 1 | M35: 2 | N35: 1 | O35: =IF($J35="Niepowodzenie rekonstrukcji",0,IF(COUNT($K35:$N35)=4,SUM($K35:$N35),"")) -> 5 | Q35: =IF($J35="Niepowodzenie rekonstrukcji",IF(COUNTIF($K35:$N35,0)=4,"OK","Ustaw C, G, A, D = 0"),IF(COUNT($K35:$N35)=0,"Nieoceniony",IF(COUNT($K35:$N35)=4,"OK","Uzupełnij oceny"))) -> OK | R35: /home/kamil/dataset/custom/bush_1/images/scen_1
A36: 35 | B36: custom_bush_1_scen_1 | C36: Custom | D36: bush_1 | E36: Naturalne | F36: 1 | G36: MapAnything | H36: =HYPERLINK("mapany/outputs/custom_bush_1_scen_1/reconstruction.glb","mapany/outputs/custom_bush_1_scen_1/reconstruction.glb") -> mapany/outputs/custom_bush_1_scen_1/reconstruction.glb | I36: IMG_9126.jpg | J36: Oceniono | K36: 2 | L36: 1 | M36: 1 | N36: 2 | O36: =IF($J36="Niepowodzenie rekonstrukcji",0,IF(COUNT($K36:$N36)=4,SUM($K36:$N36),"")) -> 6 | Q36: =IF($J36="Niepowodzenie rekonstrukcji",IF(COUNTIF($K36:$N36,0)=4,"OK","Ustaw C, G, A, D = 0"),IF(COUNT($K36:$N36)=0,"Nieoceniony",IF(COUNT($K36:$N36)=4,"OK","Uzupełnij oceny"))) -> OK | R36: /home/kamil/dataset/custom/bush_1/images/scen_1
A37: 36 | B37: custom_bush_1_scen_2 | C37: Custom | D37: bush_1 | E37: Naturalne | F37: 2 | G37: VGGT | H37: =HYPERLINK("vggt/outputs/custom_bush_1_scen_2/reconstruction.glb","vggt/outputs/custom_bush_1_scen_2/reconstruction.glb") -> vggt/outputs/custom_bush_1_scen_2/reconstruction.glb | I37: IMG_9123.jpg IMG_9126.jpg | J37: Oceniono | K37: 1 | L37: 1 | M37: 2 | N37: 1 | O37: =IF($J37="Niepowodzenie rekonstrukcji",0,IF(COUNT($K37:$N37)=4,SUM($K37:$N37),"")) -> 5 | Q37: =IF($J37="Niepowodzenie rekonstrukcji",IF(COUNTIF($K37:$N37,0)=4,"OK","Ustaw C, G, A, D = 0"),IF(COUNT($K37:$N37)=0,"Nieoceniony",IF(COUNT($K37:$N37)=4,"OK","Uzupełnij oceny"))) -> OK | R37: /home/kamil/dataset/custom/bush_1/images/scen_2
A38: 37 | B38: custom_bush_1_scen_2 | C38: Custom | D38: bush_1 | E38: Naturalne | F38: 2 | G38: MASt3R | H38: =HYPERLINK("mast3r/outputs/custom_bush_1_scen_2/reconstruction.glb","mast3r/outputs/custom_bush_1_scen_2/reconstruction.glb") -> mast3r/outputs/custom_bush_1_scen_2/reconstruction.glb | I38: IMG_9123.jpg IMG_9126.jpg | J38: Oceniono | K38: 1 | L38: 1 | M38: 2 | N38: 1 | O38: =IF($J38="Niepowodzenie rekonstrukcji",0,IF(COUNT($K38:$N38)=4,SUM($K38:$N38),"")) -> 5 | Q38: =IF($J38="Niepowodzenie rekonstrukcji",IF(COUNTIF($K38:$N38,0)=4,"OK","Ustaw C, G, A, D = 0"),IF(COUNT($K38:$N38)=0,"Nieoceniony",IF(COUNT($K38:$N38)=4,"OK","Uzupełnij oceny"))) -> OK | R38: /home/kamil/dataset/custom/bush_1/images/scen_2
A39: 38 | B39: custom_bush_1_scen_2 | C39: Custom | D39: bush_1 | E39: Naturalne | F39: 2 | G39: MapAnything | H39: =HYPERLINK("mapany/outputs/custom_bush_1_scen_2/reconstruction.glb","mapany/outputs/custom_bush_1_scen_2/reconstruction.glb") -> mapany/outputs/custom_bush_1_scen_2/reconstruction.glb | I39: IMG_9123.jpg IMG_9126.jpg | J39: Oceniono | K39: 2 | L39: 1 | M39: 1 | N39: 2 | O39: =IF($J39="Niepowodzenie rekonstrukcji",0,IF(COUNT($K39:$N39)=4,SUM($K39:$N39),"")) -> 6 | Q39: =IF($J39="Niepowodzenie rekonstrukcji",IF(COUNTIF($K39:$N39,0)=4,"OK","Ustaw C, G, A, D = 0"),IF(COUNT($K39:$N39)=0,"Nieoceniony",IF(COUNT($K39:$N39)=4,"OK","Uzupełnij oceny"))) -> OK | R39: /home/kamil/dataset/custom/bush_1/images/scen_2
A40: 39 | B40: custom_bush_1_scen_3 | C40: Custom | D40: bush_1 | E40: Naturalne | F40: 4 | G40: VGGT | H40: =HYPERLINK("vggt/outputs/custom_bush_1_scen_3/reconstruction.glb","vggt/outputs/custom_bush_1_scen_3/reconstruction.glb") -> vggt/outputs/custom_bush_1_scen_3/reconstruction.glb | I40: IMG_9123.jpg IMG_9126.jpg IMG_9128.jpg IMG_9129.jpg | J40: Oceniono | K40: 1 | L40: 1 | M40: 2 | N40: 1 | O40: =IF($J40="Niepowodzenie rekonstrukcji",0,IF(COUNT($K40:$N40)=4,SUM($K40:$N40),"")) -> 5 | Q40: =IF($J40="Niepowodzenie rekonstrukcji",IF(COUNTIF($K40:$N40,0)=4,"OK","Ustaw C, G, A, D = 0"),IF(COUNT($K40:$N40)=0,"Nieoceniony",IF(COUNT($K40:$N40)=4,"OK","Uzupełnij oceny"))) -> OK | R40: /home/kamil/dataset/custom/bush_1/images/scen_3
...

Sheet Skala
A1: Skala punktowa 0–3
A2: Kryterium | B2: 0 pkt | C2: 1 pkt | D2: 2 pkt | E2: 3 pkt
A3: C – kompletność rekonstrukcji | B3: Brak użytecznej rekonstrukcji albo jedynie pojedyncze, niepowiązane fragmenty. | C3: Zrekonstruowano niewielką część sceny; duże braki względem obrazów wejściowych. | D3: Większość istotnych elementów jest obecna, ale występują zauważalne braki. | E3: Rekonstrukcja obejmuje praktycznie wszystkie istotne elementy widoczne na obrazach.
A4: G – spójność geometryczna | B4: Nie można zidentyfikować spójnej struktury przestrzennej sceny. | C4: Poważne deformacje, przesunięcia, rozwarstwienia lub błędne położenie elementów. | D4: Ogólna geometria jest poprawna, ale występują lokalne deformacje albo niespójności. | E4: Położenie elementów, proporcje i lokalna geometria są wizualnie spójne ze źródłami.
A5: A – artefakty i szum | B5: Artefakty dominują nad rekonstrukcją i uniemożliwiają jej interpretację. | C5: Liczne punkty odstające, duchy, rozwarstwienia, duplikaty lub inne poważne artefakty. | D5: Artefakty są widoczne, ale nie uniemożliwiają interpretacji sceny. | E5: Artefakty są nieliczne i mają marginalny wpływ na odbiór rekonstrukcji.
A6: D – struktura i szczegóły | B6: Podstawowa struktura sceny jest nierozpoznawalna. | C6: Rozpoznawalne są jedynie główne bryły lub najbardziej ogólna struktura. | D6: Poprawnie odwzorowano główne elementy oraz część drobniejszych szczegółów. | E6: Dobrze zachowano zarówno główne struktury, jak i drobniejsze elementy sceny.
A7: Q = C + G + A + D, dlatego Q ∈ [0, 12].

Sheet Podsumowanie
A1: Automatyczne podsumowanie wyników
A2: Model | B2: Scenariusz | C2: Liczba obrazów | D2: Liczba przypadków | E2: Ocenione / kompletne | F2: Postęp | G2: Mediana Q | H2: Średnia Q | I2: Mediana C | J2: Średnia C | K2: Mediana G | L2: Średnia G | M2: Mediana A | N2: Średnia A | O2: Mediana D | P2: Średnia D | Q2: Min Q | R2: Max Q | S2: Niepowodzenia (Q=0) | T2: Udział niepowodzeń
A3: VGGT | B3: 1 | C3: 1 | D3: 38 | E3: =COUNT(Ocena!$O$2,Ocena!$O$13,Ocena!$O$24,Ocena!$O$35,Ocena!$O$46,Ocena!$O$57,Ocena!$O$68,Ocena!$O$79,Ocena!$O$90,Ocena!$O$101,Ocena!$O$112,Ocena!$O$123,Ocena!$O$134,Ocena!$O$145,Ocena!$O$156,Ocena!$O$167,Ocena!$O$178,Ocena!$O$189,Ocena!$O$200,Ocena!$O$211,Ocena!$O$222,Ocena!$O$233,Ocena!$O$244,Ocena!$O$255,Ocena!$O$266,Ocena!$O$277,Ocena!$O$288,Ocena!$O$299,Ocena!$O$310,Ocena!$O$321,Ocena!$O$332,Ocena!$O$343,Ocena!$O$354,Ocena!$O$355,Ocena!$O$376,Ocena!$O$387,Ocena!$O$398,Ocena!$O$409) -> 38 | F3: =IFERROR(E3/D3,0) -> 1 | G3: =IF(E3=0,"",MEDIAN(Ocena!$O$2,Ocena!$O$13,Ocena!$O$24,Ocena!$O$35,Ocena!$O$46,Ocena!$O$57,Ocena!$O$68,Ocena!$O$79,Ocena!$O$90,Ocena!$O$101,Ocena!$O$112,Ocena!$O$123,Ocena!$O$134,Ocena!$O$145,Ocena!$O$156,Ocena!$O$167,Ocena!$O$178,Ocena!$O$189,Ocena!$O$200,Ocena!$O$211,Ocena!$O$222,Ocena!$O$233,Ocena!$O$244,Ocena!$O$255,Ocena!$O$266,Ocena!$O$277,Ocena!$O$288,Ocena!$O$299,Ocena!$O$310,Ocena!$O$321,Ocena!$O$332,Ocena!$O$343,Ocena!$O$354,Ocena!$O$355,Ocena!$O$376,Ocena!$O$387,Ocena!$O$398,Ocena!$O$409)) -> 7 | H3: =IF(E3=0,"",AVERAGE(Ocena!$O$2,Ocena!$O$13,Ocena!$O$24,Ocena!$O$35,Ocena!$O$46,Ocena!$O$57,Ocena!$O$68,Ocena!$O$79,Ocena!$O$90,Ocena!$O$101,Ocena!$O$112,Ocena!$O$123,Ocena!$O$134,Ocena!$O$145,Ocena!$O$156,Ocena!$O$167,Ocena!$O$178,Ocena!$O$189,Ocena!$O$200,Ocena!$O$211,Ocena!$O$222,Ocena!$O$233,Ocena!$O$244,Ocena!$O$255,Ocena!$O$266,Ocena!$O$277,Ocena!$O$288,Ocena!$O$299,Ocena!$O$310,Ocena!$O$321,Ocena!$O$332,Ocena!$O$343,Ocena!$O$354,Ocena!$O$355,Ocena!$O$376,Ocena!$O$387,Ocena!$O$398,Ocena!$O$409)) -> 6.5526316 | I3: =IF(E3=0,"",MEDIAN(Ocena!$K$2,Ocena!$K$13,Ocena!$K$24,Ocena!$K$35,Ocena!$K$46,Ocena!$K$57,Ocena!$K$68,Ocena!$K$79,Ocena!$K$90,Ocena!$K$101,Ocena!$K$112,Ocena!$K$123,Ocena!$K$134,Ocena!$K$145,Ocena!$K$156,Ocena!$K$167,Ocena!$K$178,Ocena!$K$189,Ocena!$K$200,Ocena!$K$211,Ocena!$K$222,Ocena!$K$233,Ocena!$K$244,Ocena!$K$255,Ocena!$K$266,Ocena!$K$277,Ocena!$K$288,Ocena!$K$299,Ocena!$K$310,Ocena!$K$321,Ocena!$K$332,Ocena!$K$343,Ocena!$K$354,Ocena!$K$355,Ocena!$K$376,Ocena!$K$387,Ocena!$K$398,Ocena!$K$409)) -> 1 | J3: =IF(E3=0,"",AVERAGE(Ocena!$K$2,Ocena!$K$13,Ocena!$K$24,Ocena!$K$35,Ocena!$K$46,Ocena!$K$57,Ocena!$K$68,Ocena!$K$79,Ocena!$K$90,Ocena!$K$101,Ocena!$K$112,Ocena!$K$123,Ocena!$K$134,Ocena!$K$145,Ocena!$K$156,Ocena!$K$167,Ocena!$K$178,Ocena!$K$189,Ocena!$K$200,Ocena!$K$211,Ocena!$K$222,Ocena!$K$233,Ocena!$K$244,Ocena!$K$255,Ocena!$K$266,Ocena!$K$277,Ocena!$K$288,Ocena!$K$299,Ocena!$K$310,Ocena!$K$321,Ocena!$K$332,Ocena!$K$343,Ocena!$K$354,Ocena!$K$355,Ocena!$K$376,Ocena!$K$387,Ocena!$K$398,Ocena!$K$409)) -> 1.1052632 | K3: =IF(E3=0,"",MEDIAN(Ocena!$L$2,Ocena!$L$13,Ocena!$L$24,Ocena!$L$35,Ocena!$L$46,Ocena!$L$57,Ocena!$L$68,Ocena!$L$79,Ocena!$L$90,Ocena!$L$101,Ocena!$L$112,Ocena!$L$123,Ocena!$L$134,Ocena!$L$145,Ocena!$L$156,Ocena!$L$167,Ocena!$L$178,Ocena!$L$189,Ocena!$L$200,Ocena!$L$211,Ocena!$L$222,Ocena!$L$233,Ocena!$L$244,Ocena!$L$255,Ocena!$L$266,Ocena!$L$277,Ocena!$L$288,Ocena!$L$299,Ocena!$L$310,Ocena!$L$321,Ocena!$L$332,Ocena!$L$343,Ocena!$L$354,Ocena!$L$355,Ocena!$L$376,Ocena!$L$387,Ocena!$L$398,Ocena!$L$409)) -> 2 | L3: =IF(E3=0,"",AVERAGE(Ocena!$L$2,Ocena!$L$13,Ocena!$L$24,Ocena!$L$35,Ocena!$L$46,Ocena!$L$57,Ocena!$L$68,Ocena!$L$79,Ocena!$L$90,Ocena!$L$101,Ocena!$L$112,Ocena!$L$123,Ocena!$L$134,Ocena!$L$145,Ocena!$L$156,Ocena!$L$167,Ocena!$L$178,Ocena!$L$189,Ocena!$L$200,Ocena!$L$211,Ocena!$L$222,Ocena!$L$233,Ocena!$L$244,Ocena!$L$255,Ocena!$L$266,Ocena!$L$277,Ocena!$L$288,Ocena!$L$299,Ocena!$L$310,Ocena!$L$321,Ocena!$L$332,Ocena!$L$343,Ocena!$L$354,Ocena!$L$355,Ocena!$L$376,Ocena!$L$387,Ocena!$L$398,Ocena!$L$409)) -> 1.8421053 | M3: =IF(E3=0,"",MEDIAN(Ocena!$M$2,Ocena!$M$13,Ocena!$M$24,Ocena!$M$35,Ocena!$M$46,Ocena!$M$57,Ocena!$M$68,Ocena!$M$79,Ocena!$M$90,Ocena!$M$101,Ocena!$M$112,Ocena!$M$123,Ocena!$M$134,Ocena!$M$145,Ocena!$M$156,Ocena!$M$167,Ocena!$M$178,Ocena!$M$189,Ocena!$M$200,Ocena!$M$211,Ocena!$M$222,Ocena!$M$233,Ocena!$M$244,Ocena!$M$255,Ocena!$M$266,Ocena!$M$277,Ocena!$M$288,Ocena!$M$299,Ocena!$M$310,Ocena!$M$321,Ocena!$M$332,Ocena!$M$343,Ocena!$M$354,Ocena!$M$355,Ocena!$M$376,Ocena!$M$387,Ocena!$M$398,Ocena!$M$409)) -> 2 | N3: =IF(E3=0,"",AVERAGE(Ocena!$M$2,Ocena!$M$13,Ocena!$M$24,Ocena!$M$35,Ocena!$M$46,Ocena!$M$57,Ocena!$M$68,Ocena!$M$79,Ocena!$M$90,Ocena!$M$101,Ocena!$M$112,Ocena!$M$123,Ocena!$M$134,Ocena!$M$145,Ocena!$M$156,Ocena!$M$167,Ocena!$M$178,Ocena!$M$189,Ocena!$M$200,Ocena!$M$211,Ocena!$M$222,Ocena!$M$233,Ocena!$M$244,Ocena!$M$255,Ocena!$M$266,Ocena!$M$277,Ocena!$M$288,Ocena!$M$299,Ocena!$M$310,Ocena!$M$321,Ocena!$M$332,Ocena!$M$343,Ocena!$M$354,Ocena!$M$355,Ocena!$M$376,Ocena!$M$387,Ocena!$M$398,Ocena!$M$409)) -> 2.2368421 | O3: =IF(E3=0,"",MEDIAN(Ocena!$N$2,Ocena!$N$13,Ocena!$N$24,Ocena!$N$35,Ocena!$N$46,Ocena!$N$57,Ocena!$N$68,Ocena!$N$79,Ocena!$N$90,Ocena!$N$101,Ocena!$N$112,Ocena!$N$123,Ocena!$N$134,Ocena!$N$145,Ocena!$N$156,Ocena!$N$167,Ocena!$N$178,Ocena!$N$189,Ocena!$N$200,Ocena!$N$211,Ocena!$N$222,Ocena!$N$233,Ocena!$N$244,Ocena!$N$255,Ocena!$N$266,Ocena!$N$277,Ocena!$N$288,Ocena!$N$299,Ocena!$N$310,Ocena!$N$321,Ocena!$N$332,Ocena!$N$343,Ocena!$N$354,Ocena!$N$355,Ocena!$N$376,Ocena!$N$387,Ocena!$N$398,Ocena!$N$409)) -> 1 | P3: =IF(E3=0,"",AVERAGE(Ocena!$N$2,Ocena!$N$13,Ocena!$N$24,Ocena!$N$35,Ocena!$N$46,Ocena!$N$57,Ocena!$N$68,Ocena!$N$79,Ocena!$N$90,Ocena!$N$101,Ocena!$N$112,Ocena!$N$123,Ocena!$N$134,Ocena!$N$145,Ocena!$N$156,Ocena!$N$167,Ocena!$N$178,Ocena!$N$189,Ocena!$N$200,Ocena!$N$211,Ocena!$N$222,Ocena!$N$233,Ocena!$N$244,Ocena!$N$255,Ocena!$N$266,Ocena!$N$277,Ocena!$N$288,Ocena!$N$299,Ocena!$N$310,Ocena!$N$321,Ocena!$N$332,Ocena!$N$343,Ocena!$N$354,Ocena!$N$355,Ocena!$N$376,Ocena!$N$387,Ocena!$N$398,Ocena!$N$409)) -> 1.3684211 | Q3: =IF(E3=0,"",MIN(Ocena!$O$2,Ocena!$O$13,Ocena!$O$24,Ocena!$O$35,Ocena!$O$46,Ocena!$O$57,Ocena!$O$68,Ocena!$O$79,Ocena!$O$90,Ocena!$O$101,Ocena!$O$112,Ocena!$O$123,Ocena!$O$134,Ocena!$O$145,Ocena!$O$156,Ocena!$O$167,Ocena!$O$178,Ocena!$O$189,Ocena!$O$200,Ocena!$O$211,Ocena!$O$222,Ocena!$O$233,Ocena!$O$244,Ocena!$O$255,Ocena!$O$266,Ocena!$O$277,Ocena!$O$288,Ocena!$O$299,Ocena!$O$310,Ocena!$O$321,Ocena!$O$332,Ocena!$O$343,Ocena!$O$354,Ocena!$O$355,Ocena!$O$376,Ocena!$O$387,Ocena!$O$398,Ocena!$O$409)) -> 3 | R3: =IF(E3=0,"",MAX(Ocena!$O$2,Ocena!$O$13,Ocena!$O$24,Ocena!$O$35,Ocena!$O$46,Ocena!$O$57,Ocena!$O$68,Ocena!$O$79,Ocena!$O$90,Ocena!$O$101,Ocena!$O$112,Ocena!$O$123,Ocena!$O$134,Ocena!$O$145,Ocena!$O$156,Ocena!$O$167,Ocena!$O$178,Ocena!$O$189,Ocena!$O$200,Ocena!$O$211,Ocena!$O$222,Ocena!$O$233,Ocena!$O$244,Ocena!$O$255,Ocena!$O$266,Ocena!$O$277,Ocena!$O$288,Ocena!$O$299,Ocena!$O$310,Ocena!$O$321,Ocena!$O$332,Ocena!$O$343,Ocena!$O$354,Ocena!$O$355,Ocena!$O$376,Ocena!$O$387,Ocena!$O$398,Ocena!$O$409)) -> 10 | S3: =IF(AND(COUNT(Ocena!$K$2:$N$2)=4,COUNTIF(Ocena!$K$2:$N$2,0)=4),1,0)+IF(AND(COUNT(Ocena!$K$13:$N$13)=4,COUNTIF(Ocena!$K$13:$N$13,0)=4),1,0)+IF(AND(COUNT(Ocena!$K$24:$N$24)=4,COUNTIF(Ocena!$K$24:$N$24,0)=4),1,0)+IF(AND(COUNT(Ocena!$K$35:$N$35)=4,COUNTIF(Ocena!$K$35:$N$35,0)=4),1,0)+IF(AND(COUNT(Ocena!$K$46:$N$46)=4,COUNTIF(Ocena!$K$46:$N$46,0)=4),1,0)+IF(AND(COUNT(Ocena!$K$57:$N$57)=4,COUNTIF(Ocena!$K$57:$N$57,0)=4),1,0)+IF(AND(COUNT(Ocena!$K$68:$N$68)=4,COUNTIF(Ocena!$K$68:$N$68,0)=4),1,0)+IF(AND(COUNT(Ocena!$K$79:$N$79)=4,COUNTIF(Ocena!$K$79:$N$79,0)=4),1,0)+IF(AND(COUNT(Ocena!$K$90:$N$90)=4,COUNTIF(Ocena!$K$90:$N$90,0)=4),1,0)+IF(AND(COUNT(Ocena!$K$101:$N$101)=4,COUNTIF(Ocena!$K$101:$N$101,0)=4),1,0)+IF(AND(COUNT(Ocena!$K$112:$N$112)=4,COUNTIF(Ocena!$K$112:$N$112,0)=4),1,0)+IF(AND(COUNT(Ocena!$K$123:$N$123)=4,COUNTIF(Ocena!$K$123:$N$123,0)=4),1,0)+IF(AND(COUNT(Ocena!$K$134:$N$134)=4,COUNTIF(Ocena!$K$134:$N$134,0)=4),1,0)+IF(AND(COUNT(Ocena!$K$145:$N$145)=4,COUNTIF(Ocena!$K$145:$N$145,0)=4),1,0)+IF(AND(COUNT(Ocena!$K$156:$N$156)=4,COUNTIF(Ocena!$K$156:$N$156,0)=4),1,0)+IF(AND(COUNT(Ocena!$K$167:$N$167)=4,COUNTIF(Ocena!$K$167:$N$167,0)=4),1,0)+IF(AND(COUNT(Ocena!$K$178:$N$178)=4,COUNTIF(Ocena!$K$178:$N$178,0)=4),1,0)+IF(AND(COUNT(Ocena!$K$189:$N$189)=4,COUNTIF(Ocena!$K$189:$N$189,0)=4),1,0)+IF(AND(COUNT(Ocena!$K$200:$N$200)=4,COUNTIF(Ocena!$K$200:$N$200,0)=4),1,0)+IF(AND(COUNT(Ocena!$K$211:$N$211)=4,COUNTIF(Ocena!$K$211:$N$211,0)=4),1,0)+IF(AND(COUNT(Ocena!$K$222:$N$222)=4,COUNTIF(Ocena!$K$222:$N$222,0)=4),1,0)+IF(AND(COUNT(Ocena!$K$233:$N$233)=4,COUNTIF(Ocena!$K$233:$N$233,0)=4),1,0)+IF(AND(COUNT(Ocena!$K$244:$N$244)=4,COUNTIF(Ocena!$K$244:$N$244,0)=4),1,0)+IF(AND(COUNT(Ocena!$K$255:$N$255)=4,COUNTIF(Ocena!$K$255:$N$255,0)=4),1,0)+IF(AND(COUNT(Ocena!$K$266:$N$266)=4,COUNTIF(Ocena!$K$266:$N$266,0)=4),1,0)+IF(AND(COUNT(Ocena!$K$277:$N$277)=4,COUNTIF(Ocena!$K$277:$N$277,0)=4),1,0)+IF(AND(COUNT(Ocena!$K$288:$N$288)=4,COUNTIF(Ocena!$K$288:$N$288,0)=4),1,0)+IF(AND(COUNT(Ocena!$K$299:$N$299)=4,COUNTIF(Ocena!$K$299:$N$299,0)=4),1,0)+IF(AND(COUNT(Ocena!$K$310:$N$310)=4,COUNTIF(Ocena!$K$310:$N$310,0)=4),1,0)+IF(AND(COUNT(Ocena!$K$321:$N$321)=4,COUNTIF(Ocena!$K$321:$N$321,0)=4),1,0)+IF(AND(COUNT(Ocena!$K$332:$N$332)=4,COUNTIF(Ocena!$K$332:$N$332,0)=4),1,0)+IF(AND(COUNT(Ocena!$K$343:$N$343)=4,COUNTIF(Ocena!$K$343:$N$343,0)=4),1,0)+IF(AND(COUNT(Ocena!$K$354:$N$354)=4,COUNTIF(Ocena!$K$354:$N$354,0)=4),1,0)+IF(AND(COUNT(Ocena!$K$355:$N$355)=4,COUNTIF(Ocena!$K$355:$N$355,0)=4),1,0)+IF(AND(COUNT(Ocena!$K$376:$N$376)=4,COUNTIF(Ocena!$K$376:$N$376,0)=4),1,0)+IF(AND(COUNT(Ocena!$K$387:$N$387)=4,COUNTIF(Ocena!$K$387:$N$387,0)=4),1,0)+IF(AND(COUNT(Ocena!$K$398:$N$398)=4,COUNTIF(Ocena!$K$398:$N$398,0)=4),1,0)+IF(AND(COUNT(Ocena!$K$409:$N$409)=4,COUNTIF(Ocena!$K$409:$N$409,0)=4),1,0) -> 0 | T3: =IFERROR(S3/D3,0) -> 0
A4: VGGT | B4: 2 | C4: 2 | D4: 38 | E4: =COUNT(Ocena!$O$4,Ocena!$O$15,Ocena!$O$26,Ocena!$O$37,Ocena!$O$48,Ocena!$O$59,Ocena!$O$70,Ocena!$O$81,Ocena!$O$92,Ocena!$O$103,Ocena!$O$114,Ocena!$O$125,Ocena!$O$136,Ocena!$O$147,Ocena!$O$158,Ocena!$O$169,Ocena!$O$180,Ocena!$O$191,Ocena!$O$202,Ocena!$O$213,Ocena!$O$224,Ocena!$O$235,Ocena!$O$246,Ocena!$O$257,Ocena!$O$268,Ocena!$O$279,Ocena!$O$290,Ocena!$O$301,Ocena!$O$312,Ocena!$O$323,Ocena!$O$334,Ocena!$O$345,Ocena!$O$358,Ocena!$O$359,Ocena!$O$378,Ocena!$O$389,Ocena!$O$400,Ocena!$O$411) -> 38 | F4: =IFERROR(E4/D4,0) -> 1 | G4: =IF(E4=0,"",MEDIAN(Ocena!$O$4,Ocena!$O$15,Ocena!$O$26,Ocena!$O$37,Ocena!$O$48,Ocena!$O$59,Ocena!$O$70,Ocena!$O$81,Ocena!$O$92,Ocena!$O$103,Ocena!$O$114,Ocena!$O$125,Ocena!$O$136,Ocena!$O$147,Ocena!$O$158,Ocena!$O$169,Ocena!$O$180,Ocena!$O$191,Ocena!$O$202,Ocena!$O$213,Ocena!$O$224,Ocena!$O$235,Ocena!$O$246,Ocena!$O$257,Ocena!$O$268,Ocena!$O$279,Ocena!$O$290,Ocena!$O$301,Ocena!$O$312,Ocena!$O$323,Ocena!$O$334,Ocena!$O$345,Ocena!$O$358,Ocena!$O$359,Ocena!$O$378,Ocena!$O$389,Ocena!$O$400,Ocena!$O$411)) -> 6 | H4: =IF(E4=0,"",AVERAGE(Ocena!$O$4,Ocena!$O$15,Ocena!$O$26,Ocena!$O$37,Ocena!$O$48,Ocena!$O$59,Ocena!$O$70,Ocena!$O$81,Ocena!$O$92,Ocena!$O$103,Ocena!$O$114,Ocena!$O$125,Ocena!$O$136,Ocena!$O$147,Ocena!$O$158,Ocena!$O$169,Ocena!$O$180,Ocena!$O$191,Ocena!$O$202,Ocena!$O$213,Ocena!$O$224,Ocena!$O$235,Ocena!$O$246,Ocena!$O$257,Ocena!$O$268,Ocena!$O$279,Ocena!$O$290,Ocena!$O$301,Ocena!$O$312,Ocena!$O$323,Ocena!$O$334,Ocena!$O$345,Ocena!$O$358,Ocena!$O$359,Ocena!$O$378,Ocena!$O$389,Ocena!$O$400,Ocena!$O$411)) -> 6.4473684 | I4: =IF(E4=0,"",MEDIAN(Ocena!$K$4,Ocena!$K$15,Ocena!$K$26,Ocena!$K$37,Ocena!$K$48,Ocena!$K$59,Ocena!$K$70,Ocena!$K$81,Ocena!$K$92,Ocena!$K$103,Ocena!$K$114,Ocena!$K$125,Ocena!$K$136,Ocena!$K$147,Ocena!$K$158,Ocena!$K$169,Ocena!$K$180,Ocena!$K$191,Ocena!$K$202,Ocena!$K$213,Ocena!$K$224,Ocena!$K$235,Ocena!$K$246,Ocena!$K$257,Ocena!$K$268,Ocena!$K$279,Ocena!$K$290,Ocena!$K$301,Ocena!$K$312,Ocena!$K$323,Ocena!$K$334,Ocena!$K$345,Ocena!$K$358,Ocena!$K$359,Ocena!$K$378,Ocena!$K$389,Ocena!$K$400,Ocena!$K$411)) -> 1 | J4: =IF(E4=0,"",AVERAGE(Ocena!$K$4,Ocena!$K$15,Ocena!$K$26,Ocena!$K$37,Ocena!$K$48,Ocena!$K$59,Ocena!$K$70,Ocena!$K$81,Ocena!$K$92,Ocena!$K$103,Ocena!$K$114,Ocena!$K$125,Ocena!$K$136,Ocena!$K$147,Ocena!$K$158,Ocena!$K$169,Ocena!$K$180,Ocena!$K$191,Ocena!$K$202,Ocena!$K$213,Ocena!$K$224,Ocena!$K$235,Ocena!$K$246,Ocena!$K$257,Ocena!$K$268,Ocena!$K$279,Ocena!$K$290,Ocena!$K$301,Ocena!$K$312,Ocena!$K$323,Ocena!$K$334,Ocena!$K$345,Ocena!$K$358,Ocena!$K$359,Ocena!$K$378,Ocena!$K$389,Ocena!$K$400,Ocena!$K$411)) -> 1.2368421 | K4: =IF(E4=0,"",MEDIAN(Ocena!$L$4,Ocena!$L$15,Ocena!$L$26,Ocena!$L$37,Ocena!$L$48,Ocena!$L$59,Ocena!$L$70,Ocena!$L$81,Ocena!$L$92,Ocena!$L$103,Ocena!$L$114,Ocena!$L$125,Ocena!$L$136,Ocena!$L$147,Ocena!$L$158,Ocena!$L$169,Ocena!$L$180,Ocena!$L$191,Ocena!$L$202,Ocena!$L$213,Ocena!$L$224,Ocena!$L$235,Ocena!$L$246,Ocena!$L$257,Ocena!$L$268,Ocena!$L$279,Ocena!$L$290,Ocena!$L$301,Ocena!$L$312,Ocena!$L$323,Ocena!$L$334,Ocena!$L$345,Ocena!$L$358,Ocena!$L$359,Ocena!$L$378,Ocena!$L$389,Ocena!$L$400,Ocena!$L$411)) -> 2 | L4: =IF(E4=0,"",AVERAGE(Ocena!$L$4,Ocena!$L$15,Ocena!$L$26,Ocena!$L$37,Ocena!$L$48,Ocena!$L$59,Ocena!$L$70,Ocena!$L$81,Ocena!$L$92,Ocena!$L$103,Ocena!$L$114,Ocena!$L$125,Ocena!$L$136,Ocena!$L$147,Ocena!$L$158,Ocena!$L$169,Ocena!$L$180,Ocena!$L$191,Ocena!$L$202,Ocena!$L$213,Ocena!$L$224,Ocena!$L$235,Ocena!$L$246,Ocena!$L$257,Ocena!$L$268,Ocena!$L$279,Ocena!$L$290,Ocena!$L$301,Ocena!$L$312,Ocena!$L$323,Ocena!$L$334,Ocena!$L$345,Ocena!$L$358,Ocena!$L$359,Ocena!$L$378,Ocena!$L$389,Ocena!$L$400,Ocena!$L$411)) -> 1.7105263 | M4: =IF(E4=0,"",MEDIAN(Ocena!$M$4,Ocena!$M$15,Ocena!$M$26,Ocena!$M$37,Ocena!$M$48,Ocena!$M$59,Ocena!$M$70,Ocena!$M$81,Ocena!$M$92,Ocena!$M$103,Ocena!$M$114,Ocena!$M$125,Ocena!$M$136,Ocena!$M$147,Ocena!$M$158,Ocena!$M$169,Ocena!$M$180,Ocena!$M$191,Ocena!$M$202,Ocena!$M$213,Ocena!$M$224,Ocena!$M$235,Ocena!$M$246,Ocena!$M$257,Ocena!$M$268,Ocena!$M$279,Ocena!$M$290,Ocena!$M$301,Ocena!$M$312,Ocena!$M$323,Ocena!$M$334,Ocena!$M$345,Ocena!$M$358,Ocena!$M$359,Ocena!$M$378,Ocena!$M$389,Ocena!$M$400,Ocena!$M$411)) -> 2 | N4: =IF(E4=0,"",AVERAGE(Ocena!$M$4,Ocena!$M$15,Ocena!$M$26,Ocena!$M$37,Ocena!$M$48,Ocena!$M$59,Ocena!$M$70,Ocena!$M$81,Ocena!$M$92,Ocena!$M$103,Ocena!$M$114,Ocena!$M$125,Ocena!$M$136,Ocena!$M$147,Ocena!$M$158,Ocena!$M$169,Ocena!$M$180,Ocena!$M$191,Ocena!$M$202,Ocena!$M$213,Ocena!$M$224,Ocena!$M$235,Ocena!$M$246,Ocena!$M$257,Ocena!$M$268,Ocena!$M$279,Ocena!$M$290,Ocena!$M$301,Ocena!$M$312,Ocena!$M$323,Ocena!$M$334,Ocena!$M$345,Ocena!$M$358,Ocena!$M$359,Ocena!$M$378,Ocena!$M$389,Ocena!$M$400,Ocena!$M$411)) -> 2.0789474 | O4: =IF(E4=0,"",MEDIAN(Ocena!$N$4,Ocena!$N$15,Ocena!$N$26,Ocena!$N$37,Ocena!$N$48,Ocena!$N$59,Ocena!$N$70,Ocena!$N$81,Ocena!$N$92,Ocena!$N$103,Ocena!$N$114,Ocena!$N$125,Ocena!$N$136,Ocena!$N$147,Ocena!$N$158,Ocena!$N$169,Ocena!$N$180,Ocena!$N$191,Ocena!$N$202,Ocena!$N$213,Ocena!$N$224,Ocena!$N$235,Ocena!$N$246,Ocena!$N$257,Ocena!$N$268,Ocena!$N$279,Ocena!$N$290,Ocena!$N$301,Ocena!$N$312,Ocena!$N$323,Ocena!$N$334,Ocena!$N$345,Ocena!$N$358,Ocena!$N$359,Ocena!$N$378,Ocena!$N$389,Ocena!$N$400,Ocena!$N$411)) -> 1 | P4: =IF(E4=0,"",AVERAGE(Ocena!$N$4,Ocena!$N$15,Ocena!$N$26,Ocena!$N$37,Ocena!$N$48,Ocena!$N$59,Ocena!$N$70,Ocena!$N$81,Ocena!$N$92,Ocena!$N$103,Ocena!$N$114,Ocena!$N$125,Ocena!$N$136,Ocena!$N$147,Ocena!$N$158,Ocena!$N$169,Ocena!$N$180,Ocena!$N$191,Ocena!$N$202,Ocena!$N$213,Ocena!$N$224,Ocena!$N$235,Ocena!$N$246,Ocena!$N$257,Ocena!$N$268,Ocena!$N$279,Ocena!$N$290,Ocena!$N$301,Ocena!$N$312,Ocena!$N$323,Ocena!$N$334,Ocena!$N$345,Ocena!$N$358,Ocena!$N$359,Ocena!$N$378,Ocena!$N$389,Ocena!$N$400,Ocena!$N$411)) -> 1.4210526 | Q4: =IF(E4=0,"",MIN(Ocena!$O$4,Ocena!$O$15,Ocena!$O$26,Ocena!$O$37,Ocena!$O$48,Ocena!$O$59,Ocena!$O$70,Ocena!$O$81,Ocena!$O$92,Ocena!$O$103,Ocena!$O$114,Ocena!$O$125,Ocena!$O$136,Ocena!$O$147,Ocena!$O$158,Ocena!$O$169,Ocena!$O$180,Ocena!$O$191,Ocena!$O$202,Ocena!$O$213,Ocena!$O$224,Ocena!$O$235,Ocena!$O$246,Ocena!$O$257,Ocena!$O$268,Ocena!$O$279,Ocena!$O$290,Ocena!$O$301,Ocena!$O$312,Ocena!$O$323,Ocena!$O$334,Ocena!$O$345,Ocena!$O$358,Ocena!$O$359,Ocena!$O$378,Ocena!$O$389,Ocena!$O$400,Ocena!$O$411)) -> 3 | R4: =IF(E4=0,"",MAX(Ocena!$O$4,Ocena!$O$15,Ocena!$O$26,Ocena!$O$37,Ocena!$O$48,Ocena!$O$59,Ocena!$O$70,Ocena!$O$81,Ocena!$O$92,Ocena!$O$103,Ocena!$O$114,Ocena!$O$125,Ocena!$O$136,Ocena!$O$147,Ocena!$O$158,Ocena!$O$169,Ocena!$O$180,Ocena!$O$191,Ocena!$O$202,Ocena!$O$213,Ocena!$O$224,Ocena!$O$235,Ocena!$O$246,Ocena!$O$257,Ocena!$O$268,Ocena!$O$279,Ocena!$O$290,Ocena!$O$301,Ocena!$O$312,Ocena!$O$323,Ocena!$O$334,Ocena!$O$345,Ocena!$O$358,Ocena!$O$359,Ocena!$O$378,Ocena!$O$389,Ocena!$O$400,Ocena!$O$411)) -> 10 | S4: =IF(AND(COUNT(Ocena!$K$4:$N$4)=4,COUNTIF(Ocena!$K$4:$N$4,0)=4),1,0)+IF(AND(COUNT(Ocena!$K$15:$N$15)=4,COUNTIF(Ocena!$K$15:$N$15,0)=4),1,0)+IF(AND(COUNT(Ocena!$K$26:$N$26)=4,COUNTIF(Ocena!$K$26:$N$26,0)=4),1,0)+IF(AND(COUNT(Ocena!$K$37:$N$37)=4,COUNTIF(Ocena!$K$37:$N$37,0)=4),1,0)+IF(AND(COUNT(Ocena!$K$48:$N$48)=4,COUNTIF(Ocena!$K$48:$N$48,0)=4),1,0)+IF(AND(COUNT(Ocena!$K$59:$N$59)=4,COUNTIF(Ocena!$K$59:$N$59,0)=4),1,0)+IF(AND(COUNT(Ocena!$K$70:$N$70)=4,COUNTIF(Ocena!$K$70:$N$70,0)=4),1,0)+IF(AND(COUNT(Ocena!$K$81:$N$81)=4,COUNTIF(Ocena!$K$81:$N$81,0)=4),1,0)+IF(AND(COUNT(Ocena!$K$92:$N$92)=4,COUNTIF(Ocena!$K$92:$N$92,0)=4),1,0)+IF(AND(COUNT(Ocena!$K$103:$N$103)=4,COUNTIF(Ocena!$K$103:$N$103,0)=4),1,0)+IF(AND(COUNT(Ocena!$K$114:$N$114)=4,COUNTIF(Ocena!$K$114:$N$114,0)=4),1,0)+IF(AND(COUNT(Ocena!$K$125:$N$125)=4,COUNTIF(Ocena!$K$125:$N$125,0)=4),1,0)+IF(AND(COUNT(Ocena!$K$136:$N$136)=4,COUNTIF(Ocena!$K$136:$N$136,0)=4),1,0)+IF(AND(COUNT(Ocena!$K$147:$N$147)=4,COUNTIF(Ocena!$K$147:$N$147,0)=4),1,0)+IF(AND(COUNT(Ocena!$K$158:$N$158)=4,COUNTIF(Ocena!$K$158:$N$158,0)=4),1,0)+IF(AND(COUNT(Ocena!$K$169:$N$169)=4,COUNTIF(Ocena!$K$169:$N$169,0)=4),1,0)+IF(AND(COUNT(Ocena!$K$180:$N$180)=4,COUNTIF(Ocena!$K$180:$N$180,0)=4),1,0)+IF(AND(COUNT(Ocena!$K$191:$N$191)=4,COUNTIF(Ocena!$K$191:$N$191,0)=4),1,0)+IF(AND(COUNT(Ocena!$K$202:$N$202)=4,COUNTIF(Ocena!$K$202:$N$202,0)=4),1,0)+IF(AND(COUNT(Ocena!$K$213:$N$213)=4,COUNTIF(Ocena!$K$213:$N$213,0)=4),1,0)+IF(AND(COUNT(Ocena!$K$224:$N$224)=4,COUNTIF(Ocena!$K$224:$N$224,0)=4),1,0)+IF(AND(COUNT(Ocena!$K$235:$N$235)=4,COUNTIF(Ocena!$K$235:$N$235,0)=4),1,0)+IF(AND(COUNT(Ocena!$K$246:$N$246)=4,COUNTIF(Ocena!$K$246:$N$246,0)=4),1,0)+IF(AND(COUNT(Ocena!$K$257:$N$257)=4,COUNTIF(Ocena!$K$257:$N$257,0)=4),1,0)+IF(AND(COUNT(Ocena!$K$268:$N$268)=4,COUNTIF(Ocena!$K$268:$N$268,0)=4),1,0)+IF(AND(COUNT(Ocena!$K$279:$N$279)=4,COUNTIF(Ocena!$K$279:$N$279,0)=4),1,0)+IF(AND(COUNT(Ocena!$K$290:$N$290)=4,COUNTIF(Ocena!$K$290:$N$290,0)=4),1,0)+IF(AND(COUNT(Ocena!$K$301:$N$301)=4,COUNTIF(Ocena!$K$301:$N$301,0)=4),1,0)+IF(AND(COUNT(Ocena!$K$312:$N$312)=4,COUNTIF(Ocena!$K$312:$N$312,0)=4),1,0)+IF(AND(COUNT(Ocena!$K$323:$N$323)=4,COUNTIF(Ocena!$K$323:$N$323,0)=4),1,0)+IF(AND(COUNT(Ocena!$K$334:$N$334)=4,COUNTIF(Ocena!$K$334:$N$334,0)=4),1,0)+IF(AND(COUNT(Ocena!$K$345:$N$345)=4,COUNTIF(Ocena!$K$345:$N$345,0)=4),1,0)+IF(AND(COUNT(Ocena!$K$358:$N$358)=4,COUNTIF(Ocena!$K$358:$N$358,0)=4),1,0)+IF(AND(COUNT(Ocena!$K$359:$N$359)=4,COUNTIF(Ocena!$K$359:$N$359,0)=4),1,0)+IF(AND(COUNT(Ocena!$K$378:$N$378)=4,COUNTIF(Ocena!$K$378:$N$378,0)=4),1,0)+IF(AND(COUNT(Ocena!$K$389:$N$389)=4,COUNTIF(Ocena!$K$389:$N$389,0)=4),1,0)+IF(AND(COUNT(Ocena!$K$400:$N$400)=4,COUNTIF(Ocena!$K$400:$N$400,0)=4),1,0)+IF(AND(COUNT(Ocena!$K$411:$N$411)=4,COUNTIF(Ocena!$K$411:$N$411,0)=4),1,0) -> 0 | T4: =IFERROR(S4/D4,0) -> 0
