Workbook

Sheet Ocena
A1: Lp. | B1: Nazwa przypadku | C1: Zbiór | D1: Scena | E1: Kategoria scen | F1: Wariant | G1: Liczba obrazów (scenariusz) | H1: Model | I1: Rekonstrukcja GLB | J1: Obrazy źródłowe | K1: Status | L1: C – kompletność | M1: G – geometria | N1: A – artefakty | O1: D – struktura i szczegóły | P1: Q – suma | Q1: Uwagi jakościowe | R1: Kontrola | S1: Katalog źródłowy (WSL)
A2: 1 | B2: llff_fortress_a_scen_2 | C2: LLFF | D2: fortress | E2: Obiektowe | F2: a | G2: 2 | H2: VGGT | I2: =HYPERLINK("vggt/outputs/llff_fortress_scen_2/reconstruction.glb","vggt/outputs/llff_fortress_scen_2/reconstruction.glb") -> vggt/outputs/llff_fortress_scen_2/reconstruction.glb | J2: IMG_1800.JPG IMG_1820.JPG | K2: Oceniono | L2: 1 | M2: 1 | N2: 2 | O2: 1 | P2: =IF($K2="Niepowodzenie rekonstrukcji",0,IF(COUNT($L2:$O2)=4,SUM($L2:$O2),"")) -> 5 | R2: =IF($K2="Niepowodzenie rekonstrukcji",IF(COUNTIF($L2:$O2,0)=4,"OK","Ustaw C, G, A, D = 0"),IF(COUNT($L2:$O2)=0,"Nieoceniony",IF(COUNT($L2:$O2)=4,"OK","Uzupełnij oceny"))) -> OK | S2: /home/kamil/dataset/nerf_llff_data/fortress/images/scen_2
A3: 2 | B3: llff_fortress_b_scen_2 | C3: LLFF | D3: fortress | E3: Obiektowe | F3: b | G3: 2 | H3: VGGT | I3: =HYPERLINK("vggt/outputs_extras/llff_fortress_b_scen_2/reconstruction.glb","vggt/outputs_extras/llff_fortress_b_scen_2/reconstruction.glb") -> vggt/outputs_extras/llff_fortress_b_scen_2/reconstruction.glb | J3: IMG_1810.JPG IMG_1815.JPG | K3: Do oceny | L3: 1 | M3: 1 | N3: 2 | O3: 1 | P3: =IF($K3="Niepowodzenie rekonstrukcji",0,IF(COUNT($L3:$O3)=4,SUM($L3:$O3),"")) -> 5 | R3: =IF($K3="Niepowodzenie rekonstrukcji",IF(COUNTIF($L3:$O3,0)=4,"OK","Ustaw C, G, A, D = 0"),IF(COUNT($L3:$O3)=0,"Nieoceniony",IF(COUNT($L3:$O3)=4,"OK","Uzupełnij oceny"))) -> OK | S3: /home/kamil/dataset/nerf_llff_data/fortress_B/images/scen_2
A4: 3 | B4: llff_fortress_c_scen_2 | C4: LLFF | D4: fortress | E4: Obiektowe | F4: c | G4: 2 | H4: VGGT | I4: =HYPERLINK("vggt/outputs_extras/llff_fortress_c_scen_2/reconstruction.glb","vggt/outputs_extras/llff_fortress_c_scen_2/reconstruction.glb") -> vggt/outputs_extras/llff_fortress_c_scen_2/reconstruction.glb | J4: IMG_1820.JPG IMG_1825.JPG | K4: Do oceny | L4: 1 | M4: 1 | N4: 2 | O4: 1 | P4: =IF($K4="Niepowodzenie rekonstrukcji",0,IF(COUNT($L4:$O4)=4,SUM($L4:$O4),"")) -> 5 | R4: =IF($K4="Niepowodzenie rekonstrukcji",IF(COUNTIF($L4:$O4,0)=4,"OK","Ustaw C, G, A, D = 0"),IF(COUNT($L4:$O4)=0,"Nieoceniony",IF(COUNT($L4:$O4)=4,"OK","Uzupełnij oceny"))) -> OK | S4: /home/kamil/dataset/nerf_llff_data/fortress_C/images/scen_2
A5: 4 | B5: llff_fortress_a_scen_2 | C5: LLFF | D5: fortress | E5: Obiektowe | F5: a | G5: 2 | H5: MASt3R | I5: =HYPERLINK("mast3r/outputs/llff_fortress_scen_2/reconstruction.glb","mast3r/outputs/llff_fortress_scen_2/reconstruction.glb") -> mast3r/outputs/llff_fortress_scen_2/reconstruction.glb | J5: IMG_1800.JPG IMG_1820.JPG | K5: Oceniono | L5: 1 | M5: 1 | N5: 3 | O5: 1 | P5: =IF($K5="Niepowodzenie rekonstrukcji",0,IF(COUNT($L5:$O5)=4,SUM($L5:$O5),"")) -> 6 | R5: =IF($K5="Niepowodzenie rekonstrukcji",IF(COUNTIF($L5:$O5,0)=4,"OK","Ustaw C, G, A, D = 0"),IF(COUNT($L5:$O5)=0,"Nieoceniony",IF(COUNT($L5:$O5)=4,"OK","Uzupełnij oceny"))) -> OK | S5: /home/kamil/dataset/nerf_llff_data/fortress/images/scen_2
A6: 5 | B6: llff_fortress_b_scen_2 | C6: LLFF | D6: fortress | E6: Obiektowe | F6: b | G6: 2 | H6: MASt3R | I6: =HYPERLINK("mast3r/outputs_extras/llff_fortress_b_scen_2/reconstruction.glb","mast3r/outputs_extras/llff_fortress_b_scen_2/reconstruction.glb") -> mast3r/outputs_extras/llff_fortress_b_scen_2/reconstruction.glb | J6: IMG_1810.JPG IMG_1815.JPG | K6: Do oceny | L6: 1 | M6: 1 | N6: 3 | O6: 1 | P6: =IF($K6="Niepowodzenie rekonstrukcji",0,IF(COUNT($L6:$O6)=4,SUM($L6:$O6),"")) -> 6 | R6: =IF($K6="Niepowodzenie rekonstrukcji",IF(COUNTIF($L6:$O6,0)=4,"OK","Ustaw C, G, A, D = 0"),IF(COUNT($L6:$O6)=0,"Nieoceniony",IF(COUNT($L6:$O6)=4,"OK","Uzupełnij oceny"))) -> OK | S6: /home/kamil/dataset/nerf_llff_data/fortress_B/images/scen_2
A7: 6 | B7: llff_fortress_c_scen_2 | C7: LLFF | D7: fortress | E7: Obiektowe | F7: c | G7: 2 | H7: MASt3R | I7: =HYPERLINK("mast3r/outputs_extras/llff_fortress_c_scen_2/reconstruction.glb","mast3r/outputs_extras/llff_fortress_c_scen_2/reconstruction.glb") -> mast3r/outputs_extras/llff_fortress_c_scen_2/reconstruction.glb | J7: IMG_1820.JPG IMG_1825.JPG | K7: Do oceny | L7: 1 | M7: 1 | N7: 3 | O7: 1 | P7: =IF($K7="Niepowodzenie rekonstrukcji",0,IF(COUNT($L7:$O7)=4,SUM($L7:$O7),"")) -> 6 | R7: =IF($K7="Niepowodzenie rekonstrukcji",IF(COUNTIF($L7:$O7,0)=4,"OK","Ustaw C, G, A, D = 0"),IF(COUNT($L7:$O7)=0,"Nieoceniony",IF(COUNT($L7:$O7)=4,"OK","Uzupełnij oceny"))) -> OK | S7: /home/kamil/dataset/nerf_llff_data/fortress_C/images/scen_2
A8: 7 | B8: llff_fortress_a_scen_2 | C8: LLFF | D8: fortress | E8: Obiektowe | F8: a | G8: 2 | H8: MapAnything | I8: =HYPERLINK("mapany/outputs/llff_fortress_scen_2/reconstruction.glb","mapany/outputs/llff_fortress_scen_2/reconstruction.glb") -> mapany/outputs/llff_fortress_scen_2/reconstruction.glb | J8: IMG_1800.JPG IMG_1820.JPG | K8: Oceniono | L8: 2 | M8: 1 | N8: 3 | O8: 1 | P8: =IF($K8="Niepowodzenie rekonstrukcji",0,IF(COUNT($L8:$O8)=4,SUM($L8:$O8),"")) -> 7 | R8: =IF($K8="Niepowodzenie rekonstrukcji",IF(COUNTIF($L8:$O8,0)=4,"OK","Ustaw C, G, A, D = 0"),IF(COUNT($L8:$O8)=0,"Nieoceniony",IF(COUNT($L8:$O8)=4,"OK","Uzupełnij oceny"))) -> OK | S8: /home/kamil/dataset/nerf_llff_data/fortress/images/scen_2
A9: 8 | B9: llff_fortress_b_scen_2 | C9: LLFF | D9: fortress | E9: Obiektowe | F9: b | G9: 2 | H9: MapAnything | I9: =HYPERLINK("mapany/outputs_extras/llff_fortress_b_scen_2/reconstruction.glb","mapany/outputs_extras/llff_fortress_b_scen_2/reconstruction.glb") -> mapany/outputs_extras/llff_fortress_b_scen_2/reconstruction.glb | J9: IMG_1810.JPG IMG_1815.JPG | K9: Do oceny | L9: 2 | M9: 1 | N9: 3 | O9: 1 | P9: =IF($K9="Niepowodzenie rekonstrukcji",0,IF(COUNT($L9:$O9)=4,SUM($L9:$O9),"")) -> 7 | R9: =IF($K9="Niepowodzenie rekonstrukcji",IF(COUNTIF($L9:$O9,0)=4,"OK","Ustaw C, G, A, D = 0"),IF(COUNT($L9:$O9)=0,"Nieoceniony",IF(COUNT($L9:$O9)=4,"OK","Uzupełnij oceny"))) -> OK | S9: /home/kamil/dataset/nerf_llff_data/fortress_B/images/scen_2
A10: 9 | B10: llff_fortress_c_scen_2 | C10: LLFF | D10: fortress | E10: Obiektowe | F10: c | G10: 2 | H10: MapAnything | I10: =HYPERLINK("mapany/outputs_extras/llff_fortress_c_scen_2/reconstruction.glb","mapany/outputs_extras/llff_fortress_c_scen_2/reconstruction.glb") -> mapany/outputs_extras/llff_fortress_c_scen_2/reconstruction.glb | J10: IMG_1820.JPG IMG_1825.JPG | K10: Do oceny | L10: 2 | M10: 1 | N10: 3 | O10: 1 | P10: =IF($K10="Niepowodzenie rekonstrukcji",0,IF(COUNT($L10:$O10)=4,SUM($L10:$O10),"")) -> 7 | R10: =IF($K10="Niepowodzenie rekonstrukcji",IF(COUNTIF($L10:$O10,0)=4,"OK","Ustaw C, G, A, D = 0"),IF(COUNT($L10:$O10)=0,"Nieoceniony",IF(COUNT($L10:$O10)=4,"OK","Uzupełnij oceny"))) -> OK | S10: /home/kamil/dataset/nerf_llff_data/fortress_C/images/scen_2
A11: 10 | B11: llff_fortress_a_scen_3 | C11: LLFF | D11: fortress | E11: Obiektowe | F11: a | G11: 4 | H11: VGGT | I11: =HYPERLINK("vggt/outputs/llff_fortress_scen_3/reconstruction.glb","vggt/outputs/llff_fortress_scen_3/reconstruction.glb") -> vggt/outputs/llff_fortress_scen_3/reconstruction.glb | J11: IMG_1800.JPG IMG_1820.JPG IMG_1830.JPG IMG_1835.JPG | K11: Oceniono | L11: 1 | M11: 2 | N11: 3 | O11: 1 | P11: =IF($K11="Niepowodzenie rekonstrukcji",0,IF(COUNT($L11:$O11)=4,SUM($L11:$O11),"")) -> 7 | R11: =IF($K11="Niepowodzenie rekonstrukcji",IF(COUNTIF($L11:$O11,0)=4,"OK","Ustaw C, G, A, D = 0"),IF(COUNT($L11:$O11)=0,"Nieoceniony",IF(COUNT($L11:$O11)=4,"OK","Uzupełnij oceny"))) -> OK | S11: /home/kamil/dataset/nerf_llff_data/fortress/images/scen_3
A12: 11 | B12: llff_fortress_b_scen_3 | C12: LLFF | D12: fortress | E12: Obiektowe | F12: b | G12: 4 | H12: VGGT | I12: =HYPERLINK("vggt/outputs_extras/llff_fortress_b_scen_3/reconstruction.glb","vggt/outputs_extras/llff_fortress_b_scen_3/reconstruction.glb") -> vggt/outputs_extras/llff_fortress_b_scen_3/reconstruction.glb | J12: IMG_1800.JPG IMG_1805.JPG IMG_1810.JPG IMG_1815.JPG | K12: Do oceny | L12: 1 | M12: 2 | N12: 3 | O12: 1 | P12: =IF($K12="Niepowodzenie rekonstrukcji",0,IF(COUNT($L12:$O12)=4,SUM($L12:$O12),"")) -> 7 | R12: =IF($K12="Niepowodzenie rekonstrukcji",IF(COUNTIF($L12:$O12,0)=4,"OK","Ustaw C, G, A, D = 0"),IF(COUNT($L12:$O12)=0,"Nieoceniony",IF(COUNT($L12:$O12)=4,"OK","Uzupełnij oceny"))) -> OK | S12: /home/kamil/dataset/nerf_llff_data/fortress_B/images/scen_3
A13: 12 | B13: llff_fortress_c_scen_3 | C13: LLFF | D13: fortress | E13: Obiektowe | F13: c | G13: 4 | H13: VGGT | I13: =HYPERLINK("vggt/outputs_extras/llff_fortress_c_scen_3/reconstruction.glb","vggt/outputs_extras/llff_fortress_c_scen_3/reconstruction.glb") -> vggt/outputs_extras/llff_fortress_c_scen_3/reconstruction.glb | J13: IMG_1805.JPG IMG_1820.JPG IMG_1825.JPG IMG_1835.JPG | K13: Do oceny | L13: 1 | M13: 2 | N13: 3 | O13: 1 | P13: =IF($K13="Niepowodzenie rekonstrukcji",0,IF(COUNT($L13:$O13)=4,SUM($L13:$O13),"")) -> 7 | R13: =IF($K13="Niepowodzenie rekonstrukcji",IF(COUNTIF($L13:$O13,0)=4,"OK","Ustaw C, G, A, D = 0"),IF(COUNT($L13:$O13)=0,"Nieoceniony",IF(COUNT($L13:$O13)=4,"OK","Uzupełnij oceny"))) -> OK | S13: /home/kamil/dataset/nerf_llff_data/fortress_C/images/scen_3
A14: 13 | B14: llff_fortress_a_scen_3 | C14: LLFF | D14: fortress | E14: Obiektowe | F14: a | G14: 4 | H14: MASt3R | I14: =HYPERLINK("mast3r/outputs/llff_fortress_scen_3/reconstruction.glb","mast3r/outputs/llff_fortress_scen_3/reconstruction.glb") -> mast3r/outputs/llff_fortress_scen_3/reconstruction.glb | J14: IMG_1800.JPG IMG_1820.JPG IMG_1830.JPG IMG_1835.JPG | K14: Oceniono | L14: 1 | M14: 1 | N14: 3 | O14: 1 | P14: =IF($K14="Niepowodzenie rekonstrukcji",0,IF(COUNT($L14:$O14)=4,SUM($L14:$O14),"")) -> 6 | R14: =IF($K14="Niepowodzenie rekonstrukcji",IF(COUNTIF($L14:$O14,0)=4,"OK","Ustaw C, G, A, D = 0"),IF(COUNT($L14:$O14)=0,"Nieoceniony",IF(COUNT($L14:$O14)=4,"OK","Uzupełnij oceny"))) -> OK | S14: /home/kamil/dataset/nerf_llff_data/fortress/images/scen_3
A15: 14 | B15: llff_fortress_b_scen_3 | C15: LLFF | D15: fortress | E15: Obiektowe | F15: b | G15: 4 | H15: MASt3R | I15: =HYPERLINK("mast3r/outputs_extras/llff_fortress_b_scen_3/reconstruction.glb","mast3r/outputs_extras/llff_fortress_b_scen_3/reconstruction.glb") -> mast3r/outputs_extras/llff_fortress_b_scen_3/reconstruction.glb | J15: IMG_1800.JPG IMG_1805.JPG IMG_1810.JPG IMG_1815.JPG | K15: Do oceny | L15: 1 | M15: 1 | N15: 3 | O15: 1 | P15: =IF($K15="Niepowodzenie rekonstrukcji",0,IF(COUNT($L15:$O15)=4,SUM($L15:$O15),"")) -> 6 | R15: =IF($K15="Niepowodzenie rekonstrukcji",IF(COUNTIF($L15:$O15,0)=4,"OK","Ustaw C, G, A, D = 0"),IF(COUNT($L15:$O15)=0,"Nieoceniony",IF(COUNT($L15:$O15)=4,"OK","Uzupełnij oceny"))) -> OK | S15: /home/kamil/dataset/nerf_llff_data/fortress_B/images/scen_3
A16: 15 | B16: llff_fortress_c_scen_3 | C16: LLFF | D16: fortress | E16: Obiektowe | F16: c | G16: 4 | H16: MASt3R | I16: =HYPERLINK("mast3r/outputs_extras/llff_fortress_c_scen_3/reconstruction.glb","mast3r/outputs_extras/llff_fortress_c_scen_3/reconstruction.glb") -> mast3r/outputs_extras/llff_fortress_c_scen_3/reconstruction.glb | J16: IMG_1805.JPG IMG_1820.JPG IMG_1825.JPG IMG_1835.JPG | K16: Do oceny | L16: 1 | M16: 1 | N16: 3 | O16: 1 | P16: =IF($K16="Niepowodzenie rekonstrukcji",0,IF(COUNT($L16:$O16)=4,SUM($L16:$O16),"")) -> 6 | R16: =IF($K16="Niepowodzenie rekonstrukcji",IF(COUNTIF($L16:$O16,0)=4,"OK","Ustaw C, G, A, D = 0"),IF(COUNT($L16:$O16)=0,"Nieoceniony",IF(COUNT($L16:$O16)=4,"OK","Uzupełnij oceny"))) -> OK | S16: /home/kamil/dataset/nerf_llff_data/fortress_C/images/scen_3
A17: 16 | B17: llff_fortress_a_scen_3 | C17: LLFF | D17: fortress | E17: Obiektowe | F17: a | G17: 4 | H17: MapAnything | I17: =HYPERLINK("mapany/outputs/llff_fortress_scen_3/reconstruction.glb","mapany/outputs/llff_fortress_scen_3/reconstruction.glb") -> mapany/outputs/llff_fortress_scen_3/reconstruction.glb | J17: IMG_1800.JPG IMG_1820.JPG IMG_1830.JPG IMG_1835.JPG | K17: Oceniono | L17: 2 | M17: 2 | N17: 3 | O17: 2 | P17: =IF($K17="Niepowodzenie rekonstrukcji",0,IF(COUNT($L17:$O17)=4,SUM($L17:$O17),"")) -> 9 | R17: =IF($K17="Niepowodzenie rekonstrukcji",IF(COUNTIF($L17:$O17,0)=4,"OK","Ustaw C, G, A, D = 0"),IF(COUNT($L17:$O17)=0,"Nieoceniony",IF(COUNT($L17:$O17)=4,"OK","Uzupełnij oceny"))) -> OK | S17: /home/kamil/dataset/nerf_llff_data/fortress/images/scen_3
A18: 17 | B18: llff_fortress_b_scen_3 | C18: LLFF | D18: fortress | E18: Obiektowe | F18: b | G18: 4 | H18: MapAnything | I18: =HYPERLINK("mapany/outputs_extras/llff_fortress_b_scen_3/reconstruction.glb","mapany/outputs_extras/llff_fortress_b_scen_3/reconstruction.glb") -> mapany/outputs_extras/llff_fortress_b_scen_3/reconstruction.glb | J18: IMG_1800.JPG IMG_1805.JPG IMG_1810.JPG IMG_1815.JPG | K18: Do oceny | L18: 2 | M18: 2 | N18: 3 | O18: 2 | P18: =IF($K18="Niepowodzenie rekonstrukcji",0,IF(COUNT($L18:$O18)=4,SUM($L18:$O18),"")) -> 9 | R18: =IF($K18="Niepowodzenie rekonstrukcji",IF(COUNTIF($L18:$O18,0)=4,"OK","Ustaw C, G, A, D = 0"),IF(COUNT($L18:$O18)=0,"Nieoceniony",IF(COUNT($L18:$O18)=4,"OK","Uzupełnij oceny"))) -> OK | S18: /home/kamil/dataset/nerf_llff_data/fortress_B/images/scen_3
A19: 18 | B19: llff_fortress_c_scen_3 | C19: LLFF | D19: fortress | E19: Obiektowe | F19: c | G19: 4 | H19: MapAnything | I19: =HYPERLINK("mapany/outputs_extras/llff_fortress_c_scen_3/reconstruction.glb","mapany/outputs_extras/llff_fortress_c_scen_3/reconstruction.glb") -> mapany/outputs_extras/llff_fortress_c_scen_3/reconstruction.glb | J19: IMG_1805.JPG IMG_1820.JPG IMG_1825.JPG IMG_1835.JPG | K19: Do oceny | L19: 2 | M19: 2 | N19: 3 | O19: 2 | P19: =IF($K19="Niepowodzenie rekonstrukcji",0,IF(COUNT($L19:$O19)=4,SUM($L19:$O19),"")) -> 9 | R19: =IF($K19="Niepowodzenie rekonstrukcji",IF(COUNTIF($L19:$O19,0)=4,"OK","Ustaw C, G, A, D = 0"),IF(COUNT($L19:$O19)=0,"Nieoceniony",IF(COUNT($L19:$O19)=4,"OK","Uzupełnij oceny"))) -> OK | S19: /home/kamil/dataset/nerf_llff_data/fortress_C/images/scen_3
A20: 19 | B20: custom_gate_a_scen_2 | C20: Custom | D20: gate | E20: Zewnętrzne | F20: a | G20: 2 | H20: VGGT | I20: =HYPERLINK("vggt/outputs/custom_gate_scen_2/reconstruction.glb","vggt/outputs/custom_gate_scen_2/reconstruction.glb") -> vggt/outputs/custom_gate_scen_2/reconstruction.glb | J20: IMG_8818.jpg IMG_8826.jpg | K20: Oceniono | L20: 1 | M20: 2 | N20: 2 | O20: 1 | P20: =IF($K20="Niepowodzenie rekonstrukcji",0,IF(COUNT($L20:$O20)=4,SUM($L20:$O20),"")) -> 6 | R20: =IF($K20="Niepowodzenie rekonstrukcji",IF(COUNTIF($L20:$O20,0)=4,"OK","Ustaw C, G, A, D = 0"),IF(COUNT($L20:$O20)=0,"Nieoceniony",IF(COUNT($L20:$O20)=4,"OK","Uzupełnij oceny"))) -> OK | S20: /home/kamil/dataset/custom/gate/images/scen_2
A21: 20 | B21: custom_gate_b_scen_2 | C21: Custom | D21: gate | E21: Zewnętrzne | F21: b | G21: 2 | H21: VGGT | I21: =HYPERLINK("vggt/outputs_extras/custom_gate_b_scen_2/reconstruction.glb","vggt/outputs_extras/custom_gate_b_scen_2/reconstruction.glb") -> vggt/outputs_extras/custom_gate_b_scen_2/reconstruction.glb | J21: IMG_8816.jpg IMG_8829.jpg | K21: Do oceny | L21: 1 | M21: 2 | N21: 2 | O21: 1 | P21: =IF($K21="Niepowodzenie rekonstrukcji",0,IF(COUNT($L21:$O21)=4,SUM($L21:$O21),"")) -> 6 | R21: =IF($K21="Niepowodzenie rekonstrukcji",IF(COUNTIF($L21:$O21,0)=4,"OK","Ustaw C, G, A, D = 0"),IF(COUNT($L21:$O21)=0,"Nieoceniony",IF(COUNT($L21:$O21)=4,"OK","Uzupełnij oceny"))) -> OK | S21: /home/kamil/dataset/custom/gate_B/images/scen_2
A22: 21 | B22: custom_gate_c_scen_2 | C22: Custom | D22: gate | E22: Zewnętrzne | F22: c | G22: 2 | H22: VGGT | I22: =HYPERLINK("vggt/outputs_extras/custom_gate_c_scen_2/reconstruction.glb","vggt/outputs_extras/custom_gate_c_scen_2/reconstruction.glb") -> vggt/outputs_extras/custom_gate_c_scen_2/reconstruction.glb | J22: IMG_8823.jpg IMG_8824.jpg | K22: Do oceny | L22: 1 | M22: 2 | N22: 2 | O22: 1 | P22: =IF($K22="Niepowodzenie rekonstrukcji",0,IF(COUNT($L22:$O22)=4,SUM($L22:$O22),"")) -> 6 | R22: =IF($K22="Niepowodzenie rekonstrukcji",IF(COUNTIF($L22:$O22,0)=4,"OK","Ustaw C, G, A, D = 0"),IF(COUNT($L22:$O22)=0,"Nieoceniony",IF(COUNT($L22:$O22)=4,"OK","Uzupełnij oceny"))) -> OK | S22: /home/kamil/dataset/custom/gate_C/images/scen_2
A23: 22 | B23: custom_gate_a_scen_2 | C23: Custom | D23: gate | E23: Zewnętrzne | F23: a | G23: 2 | H23: MASt3R | I23: =HYPERLINK("mast3r/outputs/custom_gate_scen_2/reconstruction.glb","mast3r/outputs/custom_gate_scen_2/reconstruction.glb") -> mast3r/outputs/custom_gate_scen_2/reconstruction.glb | J23: IMG_8818.jpg IMG_8826.jpg | K23: Oceniono | L23: 2 | M23: 3 | N23: 3 | O23: 2 | P23: =IF($K23="Niepowodzenie rekonstrukcji",0,IF(COUNT($L23:$O23)=4,SUM($L23:$O23),"")) -> 10 | R23: =IF($K23="Niepowodzenie rekonstrukcji",IF(COUNTIF($L23:$O23,0)=4,"OK","Ustaw C, G, A, D = 0"),IF(COUNT($L23:$O23)=0,"Nieoceniony",IF(COUNT($L23:$O23)=4,"OK","Uzupełnij oceny"))) -> OK | S23: /home/kamil/dataset/custom/gate/images/scen_2
A24: 23 | B24: custom_gate_b_scen_2 | C24: Custom | D24: gate | E24: Zewnętrzne | F24: b | G24: 2 | H24: MASt3R | I24: =HYPERLINK("mast3r/outputs_extras/custom_gate_b_scen_2/reconstruction.glb","mast3r/outputs_extras/custom_gate_b_scen_2/reconstruction.glb") -> mast3r/outputs_extras/custom_gate_b_scen_2/reconstruction.glb | J24: IMG_8816.jpg IMG_8829.jpg | K24: Do oceny | L24: 2 | M24: 3 | N24: 3 | O24: 2 | P24: =IF($K24="Niepowodzenie rekonstrukcji",0,IF(COUNT($L24:$O24)=4,SUM($L24:$O24),"")) -> 10 | R24: =IF($K24="Niepowodzenie rekonstrukcji",IF(COUNTIF($L24:$O24,0)=4,"OK","Ustaw C, G, A, D = 0"),IF(COUNT($L24:$O24)=0,"Nieoceniony",IF(COUNT($L24:$O24)=4,"OK","Uzupełnij oceny"))) -> OK | S24: /home/kamil/dataset/custom/gate_B/images/scen_2
A25: 24 | B25: custom_gate_c_scen_2 | C25: Custom | D25: gate | E25: Zewnętrzne | F25: c | G25: 2 | H25: MASt3R | I25: =HYPERLINK("mast3r/outputs_extras/custom_gate_c_scen_2/reconstruction.glb","mast3r/outputs_extras/custom_gate_c_scen_2/reconstruction.glb") -> mast3r/outputs_extras/custom_gate_c_scen_2/reconstruction.glb | J25: IMG_8823.jpg IMG_8824.jpg | K25: Do oceny | L25: 2 | M25: 3 | N25: 3 | O25: 2 | P25: =IF($K25="Niepowodzenie rekonstrukcji",0,IF(COUNT($L25:$O25)=4,SUM($L25:$O25),"")) -> 10 | R25: =IF($K25="Niepowodzenie rekonstrukcji",IF(COUNTIF($L25:$O25,0)=4,"OK","Ustaw C, G, A, D = 0"),IF(COUNT($L25:$O25)=0,"Nieoceniony",IF(COUNT($L25:$O25)=4,"OK","Uzupełnij oceny"))) -> OK | S25: /home/kamil/dataset/custom/gate_C/images/scen_2
A26: 25 | B26: custom_gate_a_scen_2 | C26: Custom | D26: gate | E26: Zewnętrzne | F26: a | G26: 2 | H26: MapAnything | I26: =HYPERLINK("mapany/outputs/custom_gate_scen_2/reconstruction.glb","mapany/outputs/custom_gate_scen_2/reconstruction.glb") -> mapany/outputs/custom_gate_scen_2/reconstruction.glb | J26: IMG_8818.jpg IMG_8826.jpg | K26: Oceniono | L26: 3 | M26: 3 | N26: 2 | O26: 3 | P26: =IF($K26="Niepowodzenie rekonstrukcji",0,IF(COUNT($L26:$O26)=4,SUM($L26:$O26),"")) -> 11 | R26: =IF($K26="Niepowodzenie rekonstrukcji",IF(COUNTIF($L26:$O26,0)=4,"OK","Ustaw C, G, A, D = 0"),IF(COUNT($L26:$O26)=0,"Nieoceniony",IF(COUNT($L26:$O26)=4,"OK","Uzupełnij oceny"))) -> OK | S26: /home/kamil/dataset/custom/gate/images/scen_2
A27: 26 | B27: custom_gate_b_scen_2 | C27: Custom | D27: gate | E27: Zewnętrzne | F27: b | G27: 2 | H27: MapAnything | I27: =HYPERLINK("mapany/outputs_extras/custom_gate_b_scen_2/reconstruction.glb","mapany/outputs_extras/custom_gate_b_scen_2/reconstruction.glb") -> mapany/outputs_extras/custom_gate_b_scen_2/reconstruction.glb | J27: IMG_8816.jpg IMG_8829.jpg | K27: Do oceny | L27: 3 | M27: 3 | N27: 1 | O27: 2 | P27: =IF($K27="Niepowodzenie rekonstrukcji",0,IF(COUNT($L27:$O27)=4,SUM($L27:$O27),"")) -> 9 | R27: =IF($K27="Niepowodzenie rekonstrukcji",IF(COUNTIF($L27:$O27,0)=4,"OK","Ustaw C, G, A, D = 0"),IF(COUNT($L27:$O27)=0,"Nieoceniony",IF(COUNT($L27:$O27)=4,"OK","Uzupełnij oceny"))) -> OK | S27: /home/kamil/dataset/custom/gate_B/images/scen_2
A28: 27 | B28: custom_gate_c_scen_2 | C28: Custom | D28: gate | E28: Zewnętrzne | F28: c | G28: 2 | H28: MapAnything | I28: =HYPERLINK("mapany/outputs_extras/custom_gate_c_scen_2/reconstruction.glb","mapany/outputs_extras/custom_gate_c_scen_2/reconstruction.glb") -> mapany/outputs_extras/custom_gate_c_scen_2/reconstruction.glb | J28: IMG_8823.jpg IMG_8824.jpg | K28: Do oceny | L28: 3 | M28: 2 | N28: 2 | O28: 2 | P28: =IF($K28="Niepowodzenie rekonstrukcji",0,IF(COUNT($L28:$O28)=4,SUM($L28:$O28),"")) -> 9 | R28: =IF($K28="Niepowodzenie rekonstrukcji",IF(COUNTIF($L28:$O28,0)=4,"OK","Ustaw C, G, A, D = 0"),IF(COUNT($L28:$O28)=0,"Nieoceniony",IF(COUNT($L28:$O28)=4,"OK","Uzupełnij oceny"))) -> OK | S28: /home/kamil/dataset/custom/gate_C/images/scen_2
A29: 28 | B29: custom_gate_a_scen_3 | C29: Custom | D29: gate | E29: Zewnętrzne | F29: a | G29: 4 | H29: VGGT | I29: =HYPERLINK("vggt/outputs/custom_gate_scen_3/reconstruction.glb","vggt/outputs/custom_gate_scen_3/reconstruction.glb") -> vggt/outputs/custom_gate_scen_3/reconstruction.glb | J29: IMG_8818.jpg IMG_8823.jpg IMG_8826.jpg IMG_8829.jpg | K29: Oceniono | L29: 1 | M29: 3 | N29: 2 | O29: 1 | P29: =IF($K29="Niepowodzenie rekonstrukcji",0,IF(COUNT($L29:$O29)=4,SUM($L29:$O29),"")) -> 7 | R29: =IF($K29="Niepowodzenie rekonstrukcji",IF(COUNTIF($L29:$O29,0)=4,"OK","Ustaw C, G, A, D = 0"),IF(COUNT($L29:$O29)=0,"Nieoceniony",IF(COUNT($L29:$O29)=4,"OK","Uzupełnij oceny"))) -> OK | S29: /home/kamil/dataset/custom/gate/images/scen_3
A30: 29 | B30: custom_gate_b_scen_3 | C30: Custom | D30: gate | E30: Zewnętrzne | F30: b | G30: 4 | H30: VGGT | I30: =HYPERLINK("vggt/outputs_extras/custom_gate_b_scen_3/reconstruction.glb","vggt/outputs_extras/custom_gate_b_scen_3/reconstruction.glb") -> vggt/outputs_extras/custom_gate_b_scen_3/reconstruction.glb | J30: IMG_8816.jpg IMG_8822.jpg IMG_8828.jpg IMG_8829.jpg | K30: Do oceny | L30: 1 | M30: 3 | N30: 2 | O30: 1 | P30: =IF($K30="Niepowodzenie rekonstrukcji",0,IF(COUNT($L30:$O30)=4,SUM($L30:$O30),"")) -> 7 | R30: =IF($K30="Niepowodzenie rekonstrukcji",IF(COUNTIF($L30:$O30,0)=4,"OK","Ustaw C, G, A, D = 0"),IF(COUNT($L30:$O30)=0,"Nieoceniony",IF(COUNT($L30:$O30)=4,"OK","Uzupełnij oceny"))) -> OK | S30: /home/kamil/dataset/custom/gate_B/images/scen_3
A31: 30 | B31: custom_gate_c_scen_3 | C31: Custom | D31: gate | E31: Zewnętrzne | F31: c | G31: 4 | H31: VGGT | I31: =HYPERLINK("vggt/outputs_extras/custom_gate_c_scen_3/reconstruction.glb","vggt/outputs_extras/custom_gate_c_scen_3/reconstruction.glb") -> vggt/outputs_extras/custom_gate_c_scen_3/reconstruction.glb | J31: IMG_8822.jpg IMG_8823.jpg IMG_8824.jpg IMG_8826.jpg | K31: Do oceny | L31: 1 | M31: 3 | N31: 3 | O31: 1 | P31: =IF($K31="Niepowodzenie rekonstrukcji",0,IF(COUNT($L31:$O31)=4,SUM($L31:$O31),"")) -> 8 | R31: =IF($K31="Niepowodzenie rekonstrukcji",IF(COUNTIF($L31:$O31,0)=4,"OK","Ustaw C, G, A, D = 0"),IF(COUNT($L31:$O31)=0,"Nieoceniony",IF(COUNT($L31:$O31)=4,"OK","Uzupełnij oceny"))) -> OK | S31: /home/kamil/dataset/custom/gate_C/images/scen_3
A32: 31 | B32: custom_gate_a_scen_3 | C32: Custom | D32: gate | E32: Zewnętrzne | F32: a | G32: 4 | H32: MASt3R | I32: =HYPERLINK("mast3r/outputs/custom_gate_scen_3/reconstruction.glb","mast3r/outputs/custom_gate_scen_3/reconstruction.glb") -> mast3r/outputs/custom_gate_scen_3/reconstruction.glb | J32: IMG_8818.jpg IMG_8823.jpg IMG_8826.jpg IMG_8829.jpg | K32: Oceniono | L32: 2 | M32: 3 | N32: 2 | O32: 2 | P32: =IF($K32="Niepowodzenie rekonstrukcji",0,IF(COUNT($L32:$O32)=4,SUM($L32:$O32),"")) -> 9 | R32: =IF($K32="Niepowodzenie rekonstrukcji",IF(COUNTIF($L32:$O32,0)=4,"OK","Ustaw C, G, A, D = 0"),IF(COUNT($L32:$O32)=0,"Nieoceniony",IF(COUNT($L32:$O32)=4,"OK","Uzupełnij oceny"))) -> OK | S32: /home/kamil/dataset/custom/gate/images/scen_3
A33: 32 | B33: custom_gate_b_scen_3 | C33: Custom | D33: gate | E33: Zewnętrzne | F33: b | G33: 4 | H33: MASt3R | I33: =HYPERLINK("mast3r/outputs_extras/custom_gate_b_scen_3/reconstruction.glb","mast3r/outputs_extras/custom_gate_b_scen_3/reconstruction.glb") -> mast3r/outputs_extras/custom_gate_b_scen_3/reconstruction.glb | J33: IMG_8816.jpg IMG_8822.jpg IMG_8828.jpg IMG_8829.jpg | K33: Do oceny | L33: 2 | M33: 2 | N33: 2 | O33: 2 | P33: =IF($K33="Niepowodzenie rekonstrukcji",0,IF(COUNT($L33:$O33)=4,SUM($L33:$O33),"")) -> 8 | R33: =IF($K33="Niepowodzenie rekonstrukcji",IF(COUNTIF($L33:$O33,0)=4,"OK","Ustaw C, G, A, D = 0"),IF(COUNT($L33:$O33)=0,"Nieoceniony",IF(COUNT($L33:$O33)=4,"OK","Uzupełnij oceny"))) -> OK | S33: /home/kamil/dataset/custom/gate_B/images/scen_3
A34: 33 | B34: custom_gate_c_scen_3 | C34: Custom | D34: gate | E34: Zewnętrzne | F34: c | G34: 4 | H34: MASt3R | I34: =HYPERLINK("mast3r/outputs_extras/custom_gate_c_scen_3/reconstruction.glb","mast3r/outputs_extras/custom_gate_c_scen_3/reconstruction.glb") -> mast3r/outputs_extras/custom_gate_c_scen_3/reconstruction.glb | J34: IMG_8822.jpg IMG_8823.jpg IMG_8824.jpg IMG_8826.jpg | K34: Do oceny | L34: 2 | M34: 3 | N34: 3 | O34: 2 | P34: =IF($K34="Niepowodzenie rekonstrukcji",0,IF(COUNT($L34:$O34)=4,SUM($L34:$O34),"")) -> 10 | R34: =IF($K34="Niepowodzenie rekonstrukcji",IF(COUNTIF($L34:$O34,0)=4,"OK","Ustaw C, G, A, D = 0"),IF(COUNT($L34:$O34)=0,"Nieoceniony",IF(COUNT($L34:$O34)=4,"OK","Uzupełnij oceny"))) -> OK | S34: /home/kamil/dataset/custom/gate_C/images/scen_3
A35: 34 | B35: custom_gate_a_scen_3 | C35: Custom | D35: gate | E35: Zewnętrzne | F35: a | G35: 4 | H35: MapAnything | I35: =HYPERLINK("mapany/outputs/custom_gate_scen_3/reconstruction.glb","mapany/outputs/custom_gate_scen_3/reconstruction.glb") -> mapany/outputs/custom_gate_scen_3/reconstruction.glb | J35: IMG_8818.jpg IMG_8823.jpg IMG_8826.jpg IMG_8829.jpg | K35: Oceniono | L35: 3 | M35: 2 | N35: 2 | O35: 3 | P35: =IF($K35="Niepowodzenie rekonstrukcji",0,IF(COUNT($L35:$O35)=4,SUM($L35:$O35),"")) -> 10 | R35: =IF($K35="Niepowodzenie rekonstrukcji",IF(COUNTIF($L35:$O35,0)=4,"OK","Ustaw C, G, A, D = 0"),IF(COUNT($L35:$O35)=0,"Nieoceniony",IF(COUNT($L35:$O35)=4,"OK","Uzupełnij oceny"))) -> OK | S35: /home/kamil/dataset/custom/gate/images/scen_3
A36: 35 | B36: custom_gate_b_scen_3 | C36: Custom | D36: gate | E36: Zewnętrzne | F36: b | G36: 4 | H36: MapAnything | I36: =HYPERLINK("mapany/outputs_extras/custom_gate_b_scen_3/reconstruction.glb","mapany/outputs_extras/custom_gate_b_scen_3/reconstruction.glb") -> mapany/outputs_extras/custom_gate_b_scen_3/reconstruction.glb | J36: IMG_8816.jpg IMG_8822.jpg IMG_8828.jpg IMG_8829.jpg | K36: Do oceny | L36: 3 | M36: 2 | N36: 2 | O36: 3 | P36: =IF($K36="Niepowodzenie rekonstrukcji",0,IF(COUNT($L36:$O36)=4,SUM($L36:$O36),"")) -> 10 | R36: =IF($K36="Niepowodzenie rekonstrukcji",IF(COUNTIF($L36:$O36,0)=4,"OK","Ustaw C, G, A, D = 0"),IF(COUNT($L36:$O36)=0,"Nieoceniony",IF(COUNT($L36:$O36)=4,"OK","Uzupełnij oceny"))) -> OK | S36: /home/kamil/dataset/custom/gate_B/images/scen_3
A37: 36 | B37: custom_gate_c_scen_3 | C37: Custom | D37: gate | E37: Zewnętrzne | F37: c | G37: 4 | H37: MapAnything | I37: =HYPERLINK("mapany/outputs_extras/custom_gate_c_scen_3/reconstruction.glb","mapany/outputs_extras/custom_gate_c_scen_3/reconstruction.glb") -> mapany/outputs_extras/custom_gate_c_scen_3/reconstruction.glb | J37: IMG_8822.jpg IMG_8823.jpg IMG_8824.jpg IMG_8826.jpg | K37: Do oceny | L37: 2 | M37: 2 | N37: 1 | O37: 2 | P37: =IF($K37="Niepowodzenie rekonstrukcji",0,IF(COUNT($L37:$O37)=4,SUM($L37:$O37),"")) -> 7 | R37: =IF($K37="Niepowodzenie rekonstrukcji",IF(COUNTIF($L37:$O37,0)=4,"OK","Ustaw C, G, A, D = 0"),IF(COUNT($L37:$O37)=0,"Nieoceniony",IF(COUNT($L37:$O37)=4,"OK","Uzupełnij oceny"))) -> OK | S37: /home/kamil/dataset/custom/gate_C/images/scen_3
A38: 37 | B38: eth3d_observatory_a_scen_2 | C38: ETH3D | D38: observatory | E38: Zewnętrzne | F38: a | G38: 2 | H38: VGGT | I38: =HYPERLINK("vggt/outputs/eth3d_observatory_scen_2/reconstruction.glb","vggt/outputs/eth3d_observatory_scen_2/reconstruction.glb") -> vggt/outputs/eth3d_observatory_scen_2/reconstruction.glb | J38: DSC_1009.JPG DSC_1011.JPG | K38: Oceniono | L38: 1 | M38: 2 | N38: 1 | O38: 1 | P38: =IF($K38="Niepowodzenie rekonstrukcji",0,IF(COUNT($L38:$O38)=4,SUM($L38:$O38),"")) -> 5 | R38: =IF($K38="Niepowodzenie rekonstrukcji",IF(COUNTIF($L38:$O38,0)=4,"OK","Ustaw C, G, A, D = 0"),IF(COUNT($L38:$O38)=0,"Nieoceniony",IF(COUNT($L38:$O38)=4,"OK","Uzupełnij oceny"))) -> OK | S38: /home/kamil/dataset/eth3d/observatory/images/scen_2
A39: 38 | B39: eth3d_observatory_b_scen_2 | C39: ETH3D | D39: observatory | E39: Zewnętrzne | F39: b | G39: 2 | H39: VGGT | I39: =HYPERLINK("vggt/outputs_extras/eth3d_observatory_b_scen_2/reconstruction.glb","vggt/outputs_extras/eth3d_observatory_b_scen_2/reconstruction.glb") -> vggt/outputs_extras/eth3d_observatory_b_scen_2/reconstruction.glb | J39: DSC_1008.JPG DSC_1010.JPG | K39: Do oceny | L39: 2 | M39: 2 | N39: 1 | O39: 2 | P39: =IF($K39="Niepowodzenie rekonstrukcji",0,IF(COUNT($L39:$O39)=4,SUM($L39:$O39),"")) -> 7 | R39: =IF($K39="Niepowodzenie rekonstrukcji",IF(COUNTIF($L39:$O39,0)=4,"OK","Ustaw C, G, A, D = 0"),IF(COUNT($L39:$O39)=0,"Nieoceniony",IF(COUNT($L39:$O39)=4,"OK","Uzupełnij oceny"))) -> OK | S39: /home/kamil/dataset/eth3d/observatory_B/images/scen_2
A40: 39 | B40: eth3d_observatory_c_scen_2 | C40: ETH3D | D40: observatory | E40: Zewnętrzne | F40: c | G40: 2 | H40: VGGT | I40: =HYPERLINK("vggt/outputs_extras/eth3d_observatory_c_scen_2/reconstruction.glb","vggt/outputs_extras/eth3d_observatory_c_scen_2/reconstruction.glb") -> vggt/outputs_extras/eth3d_observatory_c_scen_2/reconstruction.glb | J40: DSC_1007.JPG DSC_1012.JPG | K40: Do oceny | L40: 1 | M40: 2 | N40: 1 | O40: 1 | P40: =IF($K40="Niepowodzenie rekonstrukcji",0,IF(COUNT($L40:$O40)=4,SUM($L40:$O40),"")) -> 5 | R40: =IF($K40="Niepowodzenie rekonstrukcji",IF(COUNTIF($L40:$O40,0)=4,"OK","Ustaw C, G, A, D = 0"),IF(COUNT($L40:$O40)=0,"Nieoceniony",IF(COUNT($L40:$O40)=4,"OK","Uzupełnij oceny"))) -> OK | S40: /home/kamil/dataset/eth3d/observatory_C/images/scen_2
...

Sheet Skala
A1: Skala punktowa 0–3
A2: Kryterium | B2: 0 pkt | C2: 1 pkt | D2: 2 pkt | E2: 3 pkt
A3: C – kompletność rekonstrukcji | B3: Brak użytecznej rekonstrukcji albo jedynie pojedyncze, niepowiązane fragmenty. | C3: Zrekonstruowano niewielką część sceny; duże braki względem obrazów wejściowych. | D3: Większość istotnych elementów jest obecna, ale występują zauważalne braki. | E3: Rekonstrukcja obejmuje praktycznie wszystkie istotne elementy widoczne na obrazach.
A4: G – spójność geometryczna | B4: Nie można zidentyfikować spójnej struktury przestrzennej sceny. | C4: Poważne deformacje, przesunięcia, rozwarstwienia lub błędne położenie elementów. | D4: Ogólna geometria jest poprawna, ale występują lokalne deformacje albo niespójności. | E4: Położenie elementów, proporcje i lokalna geometria są wizualnie spójne ze źródłami.
A5: A – artefakty i szum | B5: Artefakty dominują nad rekonstrukcją i uniemożliwiają jej interpretację. | C5: Liczne punkty odstające, duchy, rozwarstwienia, duplikaty lub inne poważne artefakty. | D5: Artefakty są widoczne, ale nie uniemożliwiają interpretacji sceny. | E5: Artefakty są nieliczne i mają marginalny wpływ na odbiór rekonstrukcji.
A6: D – struktura i szczegóły | B6: Podstawowa struktura sceny jest nierozpoznawalna. | C6: Rozpoznawalne są jedynie główne bryły lub najbardziej ogólna struktura. | D6: Poprawnie odwzorowano główne elementy oraz część drobniejszych szczegółów. | E6: Dobrze zachowano zarówno główne struktury, jak i drobniejsze elementy sceny.
A7: Q = C + G + A + D, dlatego Q ∈ [0, 12].

Sheet Podsumowanie
A1: Automatyczne podsumowanie wariantów
A2: Model | B2: Scenariusz | C2: Wariant | D2: Liczba obrazów | E2: Liczba przypadków | F2: Ocenione / kompletne | G2: Postęp | H2: Mediana Q | I2: Średnia Q | J2: Mediana C | K2: Średnia C | L2: Mediana G | M2: Średnia G | N2: Mediana A | O2: Średnia A | P2: Mediana D | Q2: Średnia D | R2: Min Q | S2: Max Q | T2: Niepowodzenia (Q=0) | U2: Udział niepowodzeń
A3: VGGT | B3: 2 | C3: a | D3: 2 | E3: 9 | F3: =COUNT(Ocena!$P$2,Ocena!$P$20,Ocena!$P$38,Ocena!$P$56,Ocena!$P$74,Ocena!$P$92,Ocena!$P$110,Ocena!$P$128,Ocena!$P$146) -> 9 | G3: =IFERROR(F3/E3,0) -> 1 | H3: =IF(F3=0,"",MEDIAN(Ocena!$P$2,Ocena!$P$20,Ocena!$P$38,Ocena!$P$56,Ocena!$P$74,Ocena!$P$92,Ocena!$P$110,Ocena!$P$128,Ocena!$P$146)) -> 6 | I3: =IF(F3=0,"",AVERAGE(Ocena!$P$2,Ocena!$P$20,Ocena!$P$38,Ocena!$P$56,Ocena!$P$74,Ocena!$P$92,Ocena!$P$110,Ocena!$P$128,Ocena!$P$146)) -> 5.8888889 | J3: =IF(F3=0,"",MEDIAN(Ocena!$L$2,Ocena!$L$20,Ocena!$L$38,Ocena!$L$56,Ocena!$L$74,Ocena!$L$92,Ocena!$L$110,Ocena!$L$128,Ocena!$L$146)) -> 1 | K3: =IF(F3=0,"",AVERAGE(Ocena!$L$2,Ocena!$L$20,Ocena!$L$38,Ocena!$L$56,Ocena!$L$74,Ocena!$L$92,Ocena!$L$110,Ocena!$L$128,Ocena!$L$146)) -> 1.2222222 | L3: =IF(F3=0,"",MEDIAN(Ocena!$M$2,Ocena!$M$20,Ocena!$M$38,Ocena!$M$56,Ocena!$M$74,Ocena!$M$92,Ocena!$M$110,Ocena!$M$128,Ocena!$M$146)) -> 2 | M3: =IF(F3=0,"",AVERAGE(Ocena!$M$2,Ocena!$M$20,Ocena!$M$38,Ocena!$M$56,Ocena!$M$74,Ocena!$M$92,Ocena!$M$110,Ocena!$M$128,Ocena!$M$146)) -> 1.6666667 | N3: =IF(F3=0,"",MEDIAN(Ocena!$N$2,Ocena!$N$20,Ocena!$N$38,Ocena!$N$56,Ocena!$N$74,Ocena!$N$92,Ocena!$N$110,Ocena!$N$128,Ocena!$N$146)) -> 1 | O3: =IF(F3=0,"",AVERAGE(Ocena!$N$2,Ocena!$N$20,Ocena!$N$38,Ocena!$N$56,Ocena!$N$74,Ocena!$N$92,Ocena!$N$110,Ocena!$N$128,Ocena!$N$146)) -> 1.5555556 | P3: =IF(F3=0,"",MEDIAN(Ocena!$O$2,Ocena!$O$20,Ocena!$O$38,Ocena!$O$56,Ocena!$O$74,Ocena!$O$92,Ocena!$O$110,Ocena!$O$128,Ocena!$O$146)) -> 1 | Q3: =IF(F3=0,"",AVERAGE(Ocena!$O$2,Ocena!$O$20,Ocena!$O$38,Ocena!$O$56,Ocena!$O$74,Ocena!$O$92,Ocena!$O$110,Ocena!$O$128,Ocena!$O$146)) -> 1.4444444 | R3: =IF(F3=0,"",MIN(Ocena!$P$2,Ocena!$P$20,Ocena!$P$38,Ocena!$P$56,Ocena!$P$74,Ocena!$P$92,Ocena!$P$110,Ocena!$P$128,Ocena!$P$146)) -> 5 | S3: =IF(F3=0,"",MAX(Ocena!$P$2,Ocena!$P$20,Ocena!$P$38,Ocena!$P$56,Ocena!$P$74,Ocena!$P$92,Ocena!$P$110,Ocena!$P$128,Ocena!$P$146)) -> 7 | T3: =IF(AND(COUNT(Ocena!$L$2:$O$2)=4,COUNTIF(Ocena!$L$2:$O$2,0)=4),1,0)+IF(AND(COUNT(Ocena!$L$20:$O$20)=4,COUNTIF(Ocena!$L$20:$O$20,0)=4),1,0)+IF(AND(COUNT(Ocena!$L$38:$O$38)=4,COUNTIF(Ocena!$L$38:$O$38,0)=4),1,0)+IF(AND(COUNT(Ocena!$L$56:$O$56)=4,COUNTIF(Ocena!$L$56:$O$56,0)=4),1,0)+IF(AND(COUNT(Ocena!$L$74:$O$74)=4,COUNTIF(Ocena!$L$74:$O$74,0)=4),1,0)+IF(AND(COUNT(Ocena!$L$92:$O$92)=4,COUNTIF(Ocena!$L$92:$O$92,0)=4),1,0)+IF(AND(COUNT(Ocena!$L$110:$O$110)=4,COUNTIF(Ocena!$L$110:$O$110,0)=4),1,0)+IF(AND(COUNT(Ocena!$L$128:$O$128)=4,COUNTIF(Ocena!$L$128:$O$128,0)=4),1,0)+IF(AND(COUNT(Ocena!$L$146:$O$146)=4,COUNTIF(Ocena!$L$146:$O$146,0)=4),1,0) -> 0 | U3: =IFERROR(T3/E3,0) -> 0
A4: VGGT | B4: 2 | C4: b | D4: 2 | E4: 9 | F4: =COUNT(Ocena!$P$3,Ocena!$P$21,Ocena!$P$39,Ocena!$P$57,Ocena!$P$75,Ocena!$P$93,Ocena!$P$111,Ocena!$P$129,Ocena!$P$147) -> 9 | G4: =IFERROR(F4/E4,0) -> 1 | H4: =IF(F4=0,"",MEDIAN(Ocena!$P$3,Ocena!$P$21,Ocena!$P$39,Ocena!$P$57,Ocena!$P$75,Ocena!$P$93,Ocena!$P$111,Ocena!$P$129,Ocena!$P$147)) -> 6 | I4: =IF(F4=0,"",AVERAGE(Ocena!$P$3,Ocena!$P$21,Ocena!$P$39,Ocena!$P$57,Ocena!$P$75,Ocena!$P$93,Ocena!$P$111,Ocena!$P$129,Ocena!$P$147)) -> 6 | J4: =IF(F4=0,"",MEDIAN(Ocena!$L$3,Ocena!$L$21,Ocena!$L$39,Ocena!$L$57,Ocena!$L$75,Ocena!$L$93,Ocena!$L$111,Ocena!$L$129,Ocena!$L$147)) -> 1 | K4: =IF(F4=0,"",AVERAGE(Ocena!$L$3,Ocena!$L$21,Ocena!$L$39,Ocena!$L$57,Ocena!$L$75,Ocena!$L$93,Ocena!$L$111,Ocena!$L$129,Ocena!$L$147)) -> 1.3333333 | L4: =IF(F4=0,"",MEDIAN(Ocena!$M$3,Ocena!$M$21,Ocena!$M$39,Ocena!$M$57,Ocena!$M$75,Ocena!$M$93,Ocena!$M$111,Ocena!$M$129,Ocena!$M$147)) -> 2 | M4: =IF(F4=0,"",AVERAGE(Ocena!$M$3,Ocena!$M$21,Ocena!$M$39,Ocena!$M$57,Ocena!$M$75,Ocena!$M$93,Ocena!$M$111,Ocena!$M$129,Ocena!$M$147)) -> 1.5555556 | N4: =IF(F4=0,"",MEDIAN(Ocena!$N$3,Ocena!$N$21,Ocena!$N$39,Ocena!$N$57,Ocena!$N$75,Ocena!$N$93,Ocena!$N$111,Ocena!$N$129,Ocena!$N$147)) -> 1 | O4: =IF(F4=0,"",AVERAGE(Ocena!$N$3,Ocena!$N$21,Ocena!$N$39,Ocena!$N$57,Ocena!$N$75,Ocena!$N$93,Ocena!$N$111,Ocena!$N$129,Ocena!$N$147)) -> 1.5555556 | P4: =IF(F4=0,"",MEDIAN(Ocena!$O$3,Ocena!$O$21,Ocena!$O$39,Ocena!$O$57,Ocena!$O$75,Ocena!$O$93,Ocena!$O$111,Ocena!$O$129,Ocena!$O$147)) -> 2 | Q4: =IF(F4=0,"",AVERAGE(Ocena!$O$3,Ocena!$O$21,Ocena!$O$39,Ocena!$O$57,Ocena!$O$75,Ocena!$O$93,Ocena!$O$111,Ocena!$O$129,Ocena!$O$147)) -> 1.5555556 | R4: =IF(F4=0,"",MIN(Ocena!$P$3,Ocena!$P$21,Ocena!$P$39,Ocena!$P$57,Ocena!$P$75,Ocena!$P$93,Ocena!$P$111,Ocena!$P$129,Ocena!$P$147)) -> 5 | S4: =IF(F4=0,"",MAX(Ocena!$P$3,Ocena!$P$21,Ocena!$P$39,Ocena!$P$57,Ocena!$P$75,Ocena!$P$93,Ocena!$P$111,Ocena!$P$129,Ocena!$P$147)) -> 7 | T4: =IF(AND(COUNT(Ocena!$L$3:$O$3)=4,COUNTIF(Ocena!$L$3:$O$3,0)=4),1,0)+IF(AND(COUNT(Ocena!$L$21:$O$21)=4,COUNTIF(Ocena!$L$21:$O$21,0)=4),1,0)+IF(AND(COUNT(Ocena!$L$39:$O$39)=4,COUNTIF(Ocena!$L$39:$O$39,0)=4),1,0)+IF(AND(COUNT(Ocena!$L$57:$O$57)=4,COUNTIF(Ocena!$L$57:$O$57,0)=4),1,0)+IF(AND(COUNT(Ocena!$L$75:$O$75)=4,COUNTIF(Ocena!$L$75:$O$75,0)=4),1,0)+IF(AND(COUNT(Ocena!$L$93:$O$93)=4,COUNTIF(Ocena!$L$93:$O$93,0)=4),1,0)+IF(AND(COUNT(Ocena!$L$111:$O$111)=4,COUNTIF(Ocena!$L$111:$O$111,0)=4),1,0)+IF(AND(COUNT(Ocena!$L$129:$O$129)=4,COUNTIF(Ocena!$L$129:$O$129,0)=4),1,0)+IF(AND(COUNT(Ocena!$L$147:$O$147)=4,COUNTIF(Ocena!$L$147:$O$147,0)=4),1,0) -> 0 | U4: =IFERROR(T4/E4,0) -> 0
A5: VGGT | B5: 2 | C5: c | D5: 2 | E5: 9 | F5: =COUNT(Ocena!$P$4,Ocena!$P$22,Ocena!$P$40,Ocena!$P$58,Ocena!$P$76,Ocena!$P$94,Ocena!$P$112,Ocena!$P$130,Ocena!$P$148) -> 9 | G5: =IFERROR(F5/E5,0) -> 1 | H5: =IF(F5=0,"",MEDIAN(Ocena!$P$4,Ocena!$P$22,Ocena!$P$40,Ocena!$P$58,Ocena!$P$76,Ocena!$P$94,Ocena!$P$112,Ocena!$P$130,Ocena!$P$148)) -> 6 | I5: =IF(F5=0,"",AVERAGE(Ocena!$P$4,Ocena!$P$22,Ocena!$P$40,Ocena!$P$58,Ocena!$P$76,Ocena!$P$94,Ocena!$P$112,Ocena!$P$130,Ocena!$P$148)) -> 6 | J5: =IF(F5=0,"",MEDIAN(Ocena!$L$4,Ocena!$L$22,Ocena!$L$40,Ocena!$L$58,Ocena!$L$76,Ocena!$L$94,Ocena!$L$112,Ocena!$L$130,Ocena!$L$148)) -> 1 | K5: =IF(F5=0,"",AVERAGE(Ocena!$L$4,Ocena!$L$22,Ocena!$L$40,Ocena!$L$58,Ocena!$L$76,Ocena!$L$94,Ocena!$L$112,Ocena!$L$130,Ocena!$L$148)) -> 1.1111111 | L5: =IF(F5=0,"",MEDIAN(Ocena!$M$4,Ocena!$M$22,Ocena!$M$40,Ocena!$M$58,Ocena!$M$76,Ocena!$M$94,Ocena!$M$112,Ocena!$M$130,Ocena!$M$148)) -> 2 | M5: =IF(F5=0,"",AVERAGE(Ocena!$M$4,Ocena!$M$22,Ocena!$M$40,Ocena!$M$58,Ocena!$M$76,Ocena!$M$94,Ocena!$M$112,Ocena!$M$130,Ocena!$M$148)) -> 1.6666667 | N5: =IF(F5=0,"",MEDIAN(Ocena!$N$4,Ocena!$N$22,Ocena!$N$40,Ocena!$N$58,Ocena!$N$76,Ocena!$N$94,Ocena!$N$112,Ocena!$N$130,Ocena!$N$148)) -> 2 | O5: =IF(F5=0,"",AVERAGE(Ocena!$N$4,Ocena!$N$22,Ocena!$N$40,Ocena!$N$58,Ocena!$N$76,Ocena!$N$94,Ocena!$N$112,Ocena!$N$130,Ocena!$N$148)) -> 1.7777778 | P5: =IF(F5=0,"",MEDIAN(Ocena!$O$4,Ocena!$O$22,Ocena!$O$40,Ocena!$O$58,Ocena!$O$76,Ocena!$O$94,Ocena!$O$112,Ocena!$O$130,Ocena!$O$148)) -> 1 | Q5: =IF(F5=0,"",AVERAGE(Ocena!$O$4,Ocena!$O$22,Ocena!$O$40,Ocena!$O$58,Ocena!$O$76,Ocena!$O$94,Ocena!$O$112,Ocena!$O$130,Ocena!$O$148)) -> 1.4444444 | R5: =IF(F5=0,"",MIN(Ocena!$P$4,Ocena!$P$22,Ocena!$P$40,Ocena!$P$58,Ocena!$P$76,Ocena!$P$94,Ocena!$P$112,Ocena!$P$130,Ocena!$P$148)) -> 5 | S5: =IF(F5=0,"",MAX(Ocena!$P$4,Ocena!$P$22,Ocena!$P$40,Ocena!$P$58,Ocena!$P$76,Ocena!$P$94,Ocena!$P$112,Ocena!$P$130,Ocena!$P$148)) -> 7 | T5: =IF(AND(COUNT(Ocena!$L$4:$O$4)=4,COUNTIF(Ocena!$L$4:$O$4,0)=4),1,0)+IF(AND(COUNT(Ocena!$L$22:$O$22)=4,COUNTIF(Ocena!$L$22:$O$22,0)=4),1,0)+IF(AND(COUNT(Ocena!$L$40:$O$40)=4,COUNTIF(Ocena!$L$40:$O$40,0)=4),1,0)+IF(AND(COUNT(Ocena!$L$58:$O$58)=4,COUNTIF(Ocena!$L$58:$O$58,0)=4),1,0)+IF(AND(COUNT(Ocena!$L$76:$O$76)=4,COUNTIF(Ocena!$L$76:$O$76,0)=4),1,0)+IF(AND(COUNT(Ocena!$L$94:$O$94)=4,COUNTIF(Ocena!$L$94:$O$94,0)=4),1,0)+IF(AND(COUNT(Ocena!$L$112:$O$112)=4,COUNTIF(Ocena!$L$112:$O$112,0)=4),1,0)+IF(AND(COUNT(Ocena!$L$130:$O$130)=4,COUNTIF(Ocena!$L$130:$O$130,0)=4),1,0)+IF(AND(COUNT(Ocena!$L$148:$O$148)=4,COUNTIF(Ocena!$L$148:$O$148,0)=4),1,0) -> 0 | U5: =IFERROR(T5/E5,0) -> 0
A6: VGGT | B6: 4 | C6: a | D6: 4 | E6: 9 | F6: =COUNT(Ocena!$P$11,Ocena!$P$29,Ocena!$P$47,Ocena!$P$65,Ocena!$P$83,Ocena!$P$101,Ocena!$P$119,Ocena!$P$137,Ocena!$P$155) -> 9 | G6: =IFERROR(F6/E6,0) -> 1 | H6: =IF(F6=0,"",MEDIAN(Ocena!$P$11,Ocena!$P$29,Ocena!$P$47,Ocena!$P$65,Ocena!$P$83,Ocena!$P$101,Ocena!$P$119,Ocena!$P$137,Ocena!$P$155)) -> 7 | I6: =IF(F6=0,"",AVERAGE(Ocena!$P$11,Ocena!$P$29,Ocena!$P$47,Ocena!$P$65,Ocena!$P$83,Ocena!$P$101,Ocena!$P$119,Ocena!$P$137,Ocena!$P$155)) -> 6.5555556 | J6: =IF(F6=0,"",MEDIAN(Ocena!$L$11,Ocena!$L$29,Ocena!$L$47,Ocena!$L$65,Ocena!$L$83,Ocena!$L$101,Ocena!$L$119,Ocena!$L$137,Ocena!$L$155)) -> 1 | K6: =IF(F6=0,"",AVERAGE(Ocena!$L$11,Ocena!$L$29,Ocena!$L$47,Ocena!$L$65,Ocena!$L$83,Ocena!$L$101,Ocena!$L$119,Ocena!$L$137,Ocena!$L$155)) -> 1.3333333 | L6: =IF(F6=0,"",MEDIAN(Ocena!$M$11,Ocena!$M$29,Ocena!$M$47,Ocena!$M$65,Ocena!$M$83,Ocena!$M$101,Ocena!$M$119,Ocena!$M$137,Ocena!$M$155)) -> 2 | M6: =IF(F6=0,"",AVERAGE(Ocena!$M$11,Ocena!$M$29,Ocena!$M$47,Ocena!$M$65,Ocena!$M$83,Ocena!$M$101,Ocena!$M$119,Ocena!$M$137,Ocena!$M$155)) -> 1.8888889 | N6: =IF(F6=0,"",MEDIAN(Ocena!$N$11,Ocena!$N$29,Ocena!$N$47,Ocena!$N$65,Ocena!$N$83,Ocena!$N$101,Ocena!$N$119,Ocena!$N$137,Ocena!$N$155)) -> 2 | O6: =IF(F6=0,"",AVERAGE(Ocena!$N$11,Ocena!$N$29,Ocena!$N$47,Ocena!$N$65,Ocena!$N$83,Ocena!$N$101,Ocena!$N$119,Ocena!$N$137,Ocena!$N$155)) -> 1.8888889 | P6: =IF(F6=0,"",MEDIAN(Ocena!$O$11,Ocena!$O$29,Ocena!$O$47,Ocena!$O$65,Ocena!$O$83,Ocena!$O$101,Ocena!$O$119,Ocena!$O$137,Ocena!$O$155)) -> 1 | Q6: =IF(F6=0,"",AVERAGE(Ocena!$O$11,Ocena!$O$29,Ocena!$O$47,Ocena!$O$65,Ocena!$O$83,Ocena!$O$101,Ocena!$O$119,Ocena!$O$137,Ocena!$O$155)) -> 1.4444444 | R6: =IF(F6=0,"",MIN(Ocena!$P$11,Ocena!$P$29,Ocena!$P$47,Ocena!$P$65,Ocena!$P$83,Ocena!$P$101,Ocena!$P$119,Ocena!$P$137,Ocena!$P$155)) -> 5 | S6: =IF(F6=0,"",MAX(Ocena!$P$11,Ocena!$P$29,Ocena!$P$47,Ocena!$P$65,Ocena!$P$83,Ocena!$P$101,Ocena!$P$119,Ocena!$P$137,Ocena!$P$155)) -> 8 | T6: =IF(AND(COUNT(Ocena!$L$11:$O$11)=4,COUNTIF(Ocena!$L$11:$O$11,0)=4),1,0)+IF(AND(COUNT(Ocena!$L$29:$O$29)=4,COUNTIF(Ocena!$L$29:$O$29,0)=4),1,0)+IF(AND(COUNT(Ocena!$L$47:$O$47)=4,COUNTIF(Ocena!$L$47:$O$47,0)=4),1,0)+IF(AND(COUNT(Ocena!$L$65:$O$65)=4,COUNTIF(Ocena!$L$65:$O$65,0)=4),1,0)+IF(AND(COUNT(Ocena!$L$83:$O$83)=4,COUNTIF(Ocena!$L$83:$O$83,0)=4),1,0)+IF(AND(COUNT(Ocena!$L$101:$O$101)=4,COUNTIF(Ocena!$L$101:$O$101,0)=4),1,0)+IF(AND(COUNT(Ocena!$L$119:$O$119)=4,COUNTIF(Ocena!$L$119:$O$119,0)=4),1,0)+IF(AND(COUNT(Ocena!$L$137:$O$137)=4,COUNTIF(Ocena!$L$137:$O$137,0)=4),1,0)+IF(AND(COUNT(Ocena!$L$155:$O$155)=4,COUNTIF(Ocena!$L$155:$O$155,0)=4),1,0) -> 0 | U6: =IFERROR(T6/E6,0) -> 0
A7: VGGT | B7: 4 | C7: b | D7: 4 | E7: 9 | F7: =COUNT(Ocena!$P$12,Ocena!$P$30,Ocena!$P$48,Ocena!$P$66,Ocena!$P$84,Ocena!$P$102,Ocena!$P$120,Ocena!$P$138,Ocena!$P$156) -> 9 | G7: =IFERROR(F7/E7,0) -> 1 | H7: =IF(F7=0,"",MEDIAN(Ocena!$P$12,Ocena!$P$30,Ocena!$P$48,Ocena!$P$66,Ocena!$P$84,Ocena!$P$102,Ocena!$P$120,Ocena!$P$138,Ocena!$P$156)) -> 6 | I7: =IF(F7=0,"",AVERAGE(Ocena!$P$12,Ocena!$P$30,Ocena!$P$48,Ocena!$P$66,Ocena!$P$84,Ocena!$P$102,Ocena!$P$120,Ocena!$P$138,Ocena!$P$156)) -> 6.4444444 | J7: =IF(F7=0,"",MEDIAN(Ocena!$L$12,Ocena!$L$30,Ocena!$L$48,Ocena!$L$66,Ocena!$L$84,Ocena!$L$102,Ocena!$L$120,Ocena!$L$138,Ocena!$L$156)) -> 1 | K7: =IF(F7=0,"",AVERAGE(Ocena!$L$12,Ocena!$L$30,Ocena!$L$48,Ocena!$L$66,Ocena!$L$84,Ocena!$L$102,Ocena!$L$120,Ocena!$L$138,Ocena!$L$156)) -> 1.3333333 | L7: =IF(F7=0,"",MEDIAN(Ocena!$M$12,Ocena!$M$30,Ocena!$M$48,Ocena!$M$66,Ocena!$M$84,Ocena!$M$102,Ocena!$M$120,Ocena!$M$138,Ocena!$M$156)) -> 2 | M7: =IF(F7=0,"",AVERAGE(Ocena!$M$12,Ocena!$M$30,Ocena!$M$48,Ocena!$M$66,Ocena!$M$84,Ocena!$M$102,Ocena!$M$120,Ocena!$M$138,Ocena!$M$156)) -> 1.8888889 | N7: =IF(F7=0,"",MEDIAN(Ocena!$N$12,Ocena!$N$30,Ocena!$N$48,Ocena!$N$66,Ocena!$N$84,Ocena!$N$102,Ocena!$N$120,Ocena!$N$138,Ocena!$N$156)) -> 2 | O7: =IF(F7=0,"",AVERAGE(Ocena!$N$12,Ocena!$N$30,Ocena!$N$48,Ocena!$N$66,Ocena!$N$84,Ocena!$N$102,Ocena!$N$120,Ocena!$N$138,Ocena!$N$156)) -> 1.7777778 | P7: =IF(F7=0,"",MEDIAN(Ocena!$O$12,Ocena!$O$30,Ocena!$O$48,Ocena!$O$66,Ocena!$O$84,Ocena!$O$102,Ocena!$O$120,Ocena!$O$138,Ocena!$O$156)) -> 1 | Q7: =IF(F7=0,"",AVERAGE(Ocena!$O$12,Ocena!$O$30,Ocena!$O$48,Ocena!$O$66,Ocena!$O$84,Ocena!$O$102,Ocena!$O$120,Ocena!$O$138,Ocena!$O$156)) -> 1.4444444 | R7: =IF(F7=0,"",MIN(Ocena!$P$12,Ocena!$P$30,Ocena!$P$48,Ocena!$P$66,Ocena!$P$84,Ocena!$P$102,Ocena!$P$120,Ocena!$P$138,Ocena!$P$156)) -> 5 | S7: =IF(F7=0,"",MAX(Ocena!$P$12,Ocena!$P$30,Ocena!$P$48,Ocena!$P$66,Ocena!$P$84,Ocena!$P$102,Ocena!$P$120,Ocena!$P$138,Ocena!$P$156)) -> 8 | T7: =IF(AND(COUNT(Ocena!$L$12:$O$12)=4,COUNTIF(Ocena!$L$12:$O$12,0)=4),1,0)+IF(AND(COUNT(Ocena!$L$30:$O$30)=4,COUNTIF(Ocena!$L$30:$O$30,0)=4),1,0)+IF(AND(COUNT(Ocena!$L$48:$O$48)=4,COUNTIF(Ocena!$L$48:$O$48,0)=4),1,0)+IF(AND(COUNT(Ocena!$L$66:$O$66)=4,COUNTIF(Ocena!$L$66:$O$66,0)=4),1,0)+IF(AND(COUNT(Ocena!$L$84:$O$84)=4,COUNTIF(Ocena!$L$84:$O$84,0)=4),1,0)+IF(AND(COUNT(Ocena!$L$102:$O$102)=4,COUNTIF(Ocena!$L$102:$O$102,0)=4),1,0)+IF(AND(COUNT(Ocena!$L$120:$O$120)=4,COUNTIF(Ocena!$L$120:$O$120,0)=4),1,0)+IF(AND(COUNT(Ocena!$L$138:$O$138)=4,COUNTIF(Ocena!$L$138:$O$138,0)=4),1,0)+IF(AND(COUNT(Ocena!$L$156:$O$156)=4,COUNTIF(Ocena!$L$156:$O$156,0)=4),1,0) -> 0 | U7: =IFERROR(T7/E7,0) -> 0
A8: VGGT | B8: 4 | C8: c | D8: 4 | E8: 9 | F8: =COUNT(Ocena!$P$13,Ocena!$P$31,Ocena!$P$49,Ocena!$P$67,Ocena!$P$85,Ocena!$P$103,Ocena!$P$121,Ocena!$P$139,Ocena!$P$157) -> 9 | G8: =IFERROR(F8/E8,0) -> 1 | H8: =IF(F8=0,"",MEDIAN(Ocena!$P$13,Ocena!$P$31,Ocena!$P$49,Ocena!$P$67,Ocena!$P$85,Ocena!$P$103,Ocena!$P$121,Ocena!$P$139,Ocena!$P$157)) -> 7 | I8: =IF(F8=0,"",AVERAGE(Ocena!$P$13,Ocena!$P$31,Ocena!$P$49,Ocena!$P$67,Ocena!$P$85,Ocena!$P$103,Ocena!$P$121,Ocena!$P$139,Ocena!$P$157)) -> 6.7777778 | J8: =IF(F8=0,"",MEDIAN(Ocena!$L$13,Ocena!$L$31,Ocena!$L$49,Ocena!$L$67,Ocena!$L$85,Ocena!$L$103,Ocena!$L$121,Ocena!$L$139,Ocena!$L$157)) -> 1 | K8: =IF(F8=0,"",AVERAGE(Ocena!$L$13,Ocena!$L$31,Ocena!$L$49,Ocena!$L$67,Ocena!$L$85,Ocena!$L$103,Ocena!$L$121,Ocena!$L$139,Ocena!$L$157)) -> 1.2222222 | L8: =IF(F8=0,"",MEDIAN(Ocena!$M$13,Ocena!$M$31,Ocena!$M$49,Ocena!$M$67,Ocena!$M$85,Ocena!$M$103,Ocena!$M$121,Ocena!$M$139,Ocena!$M$157)) -> 2 | M8: =IF(F8=0,"",AVERAGE(Ocena!$M$13,Ocena!$M$31,Ocena!$M$49,Ocena!$M$67,Ocena!$M$85,Ocena!$M$103,Ocena!$M$121,Ocena!$M$139,Ocena!$M$157)) -> 2.1111111 | N8: =IF(F8=0,"",MEDIAN(Ocena!$N$13,Ocena!$N$31,Ocena!$N$49,Ocena!$N$67,Ocena!$N$85,Ocena!$N$103,Ocena!$N$121,Ocena!$N$139,Ocena!$N$157)) -> 2 | O8: =IF(F8=0,"",AVERAGE(Ocena!$N$13,Ocena!$N$31,Ocena!$N$49,Ocena!$N$67,Ocena!$N$85,Ocena!$N$103,Ocena!$N$121,Ocena!$N$139,Ocena!$N$157)) -> 2 | P8: =IF(F8=0,"",MEDIAN(Ocena!$O$13,Ocena!$O$31,Ocena!$O$49,Ocena!$O$67,Ocena!$O$85,Ocena!$O$103,Ocena!$O$121,Ocena!$O$139,Ocena!$O$157)) -> 1 | Q8: =IF(F8=0,"",AVERAGE(Ocena!$O$13,Ocena!$O$31,Ocena!$O$49,Ocena!$O$67,Ocena!$O$85,Ocena!$O$103,Ocena!$O$121,Ocena!$O$139,Ocena!$O$157)) -> 1.4444444 | R8: =IF(F8=0,"",MIN(Ocena!$P$13,Ocena!$P$31,Ocena!$P$49,Ocena!$P$67,Ocena!$P$85,Ocena!$P$103,Ocena!$P$121,Ocena!$P$139,Ocena!$P$157)) -> 5 | S8: =IF(F8=0,"",MAX(Ocena!$P$13,Ocena!$P$31,Ocena!$P$49,Ocena!$P$67,Ocena!$P$85,Ocena!$P$103,Ocena!$P$121,Ocena!$P$139,Ocena!$P$157)) -> 9 | T8: =IF(AND(COUNT(Ocena!$L$13:$O$13)=4,COUNTIF(Ocena!$L$13:$O$13,0)=4),1,0)+IF(AND(COUNT(Ocena!$L$31:$O$31)=4,COUNTIF(Ocena!$L$31:$O$31,0)=4),1,0)+IF(AND(COUNT(Ocena!$L$49:$O$49)=4,COUNTIF(Ocena!$L$49:$O$49,0)=4),1,0)+IF(AND(COUNT(Ocena!$L$67:$O$67)=4,COUNTIF(Ocena!$L$67:$O$67,0)=4),1,0)+IF(AND(COUNT(Ocena!$L$85:$O$85)=4,COUNTIF(Ocena!$L$85:$O$85,0)=4),1,0)+IF(AND(COUNT(Ocena!$L$103:$O$103)=4,COUNTIF(Ocena!$L$103:$O$103,0)=4),1,0)+IF(AND(COUNT(Ocena!$L$121:$O$121)=4,COUNTIF(Ocena!$L$121:$O$121,0)=4),1,0)+IF(AND(COUNT(Ocena!$L$139:$O$139)=4,COUNTIF(Ocena!$L$139:$O$139,0)=4),1,0)+IF(AND(COUNT(Ocena!$L$157:$O$157)=4,COUNTIF(Ocena!$L$157:$O$157,0)=4),1,0) -> 0 | U8: =IFERROR(T8/E8,0) -> 0
A9: MASt3R | B9: 2 | C9: a | D9: 2 | E9: 9 | F9: =COUNT(Ocena!$P$5,Ocena!$P$23,Ocena!$P$41,Ocena!$P$59,Ocena!$P$77,Ocena!$P$95,Ocena!$P$113,Ocena!$P$131,Ocena!$P$149) -> 9 | G9: =IFERROR(F9/E9,0) -> 1 | H9: =IF(F9=0,"",MEDIAN(Ocena!$P$5,Ocena!$P$23,Ocena!$P$41,Ocena!$P$59,Ocena!$P$77,Ocena!$P$95,Ocena!$P$113,Ocena!$P$131,Ocena!$P$149)) -> 6 | I9: =IF(F9=0,"",AVERAGE(Ocena!$P$5,Ocena!$P$23,Ocena!$P$41,Ocena!$P$59,Ocena!$P$77,Ocena!$P$95,Ocena!$P$113,Ocena!$P$131,Ocena!$P$149)) -> 6.2222222 | J9: =IF(F9=0,"",MEDIAN(Ocena!$L$5,Ocena!$L$23,Ocena!$L$41,Ocena!$L$59,Ocena!$L$77,Ocena!$L$95,Ocena!$L$113,Ocena!$L$131,Ocena!$L$149)) -> 1 | K9: =IF(F9=0,"",AVERAGE(Ocena!$L$5,Ocena!$L$23,Ocena!$L$41,Ocena!$L$59,Ocena!$L$77,Ocena!$L$95,Ocena!$L$113,Ocena!$L$131,Ocena!$L$149)) -> 1.4444444 | L9: =IF(F9=0,"",MEDIAN(Ocena!$M$5,Ocena!$M$23,Ocena!$M$41,Ocena!$M$59,Ocena!$M$77,Ocena!$M$95,Ocena!$M$113,Ocena!$M$131,Ocena!$M$149)) -> 1 | M9: =IF(F9=0,"",AVERAGE(Ocena!$M$5,Ocena!$M$23,Ocena!$M$41,Ocena!$M$59,Ocena!$M$77,Ocena!$M$95,Ocena!$M$113,Ocena!$M$131,Ocena!$M$149)) -> 1.4444444 | N9: =IF(F9=0,"",MEDIAN(Ocena!$N$5,Ocena!$N$23,Ocena!$N$41,Ocena!$N$59,Ocena!$N$77,Ocena!$N$95,Ocena!$N$113,Ocena!$N$131,Ocena!$N$149)) -> 2 | O9: =IF(F9=0,"",AVERAGE(Ocena!$N$5,Ocena!$N$23,Ocena!$N$41,Ocena!$N$59,Ocena!$N$77,Ocena!$N$95,Ocena!$N$113,Ocena!$N$131,Ocena!$N$149)) -> 1.8888889 | P9: =IF(F9=0,"",MEDIAN(Ocena!$O$5,Ocena!$O$23,Ocena!$O$41,Ocena!$O$59,Ocena!$O$77,Ocena!$O$95,Ocena!$O$113,Ocena!$O$131,Ocena!$O$149)) -> 1 | Q9: =IF(F9=0,"",AVERAGE(Ocena!$O$5,Ocena!$O$23,Ocena!$O$41,Ocena!$O$59,Ocena!$O$77,Ocena!$O$95,Ocena!$O$113,Ocena!$O$131,Ocena!$O$149)) -> 1.4444444 | R9: =IF(F9=0,"",MIN(Ocena!$P$5,Ocena!$P$23,Ocena!$P$41,Ocena!$P$59,Ocena!$P$77,Ocena!$P$95,Ocena!$P$113,Ocena!$P$131,Ocena!$P$149)) -> 5 | S9: =IF(F9=0,"",MAX(Ocena!$P$5,Ocena!$P$23,Ocena!$P$41,Ocena!$P$59,Ocena!$P$77,Ocena!$P$95,Ocena!$P$113,Ocena!$P$131,Ocena!$P$149)) -> 10 | T9: =IF(AND(COUNT(Ocena!$L$5:$O$5)=4,COUNTIF(Ocena!$L$5:$O$5,0)=4),1,0)+IF(AND(COUNT(Ocena!$L$23:$O$23)=4,COUNTIF(Ocena!$L$23:$O$23,0)=4),1,0)+IF(AND(COUNT(Ocena!$L$41:$O$41)=4,COUNTIF(Ocena!$L$41:$O$41,0)=4),1,0)+IF(AND(COUNT(Ocena!$L$59:$O$59)=4,COUNTIF(Ocena!$L$59:$O$59,0)=4),1,0)+IF(AND(COUNT(Ocena!$L$77:$O$77)=4,COUNTIF(Ocena!$L$77:$O$77,0)=4),1,0)+IF(AND(COUNT(Ocena!$L$95:$O$95)=4,COUNTIF(Ocena!$L$95:$O$95,0)=4),1,0)+IF(AND(COUNT(Ocena!$L$113:$O$113)=4,COUNTIF(Ocena!$L$113:$O$113,0)=4),1,0)+IF(AND(COUNT(Ocena!$L$131:$O$131)=4,COUNTIF(Ocena!$L$131:$O$131,0)=4),1,0)+IF(AND(COUNT(Ocena!$L$149:$O$149)=4,COUNTIF(Ocena!$L$149:$O$149,0)=4),1,0) -> 0 | U9: =IFERROR(T9/E9,0) -> 0
A10: MASt3R | B10: 2 | C10: b | D10: 2 | E10: 9 | F10: =COUNT(Ocena!$P$6,Ocena!$P$24,Ocena!$P$42,Ocena!$P$60,Ocena!$P$78,Ocena!$P$96,Ocena!$P$114,Ocena!$P$132,Ocena!$P$150) -> 9 | G10: =IFERROR(F10/E10,0) -> 1 | H10: =IF(F10=0,"",MEDIAN(Ocena!$P$6,Ocena!$P$24,Ocena!$P$42,Ocena!$P$60,Ocena!$P$78,Ocena!$P$96,Ocena!$P$114,Ocena!$P$132,Ocena!$P$150)) -> 6 | I10: =IF(F10=0,"",AVERAGE(Ocena!$P$6,Ocena!$P$24,Ocena!$P$42,Ocena!$P$60,Ocena!$P$78,Ocena!$P$96,Ocena!$P$114,Ocena!$P$132,Ocena!$P$150)) -> 6.1111111 | J10: =IF(F10=0,"",MEDIAN(Ocena!$L$6,Ocena!$L$24,Ocena!$L$42,Ocena!$L$60,Ocena!$L$78,Ocena!$L$96,Ocena!$L$114,Ocena!$L$132,Ocena!$L$150)) -> 1 | K10: =IF(F10=0,"",AVERAGE(Ocena!$L$6,Ocena!$L$24,Ocena!$L$42,Ocena!$L$60,Ocena!$L$78,Ocena!$L$96,Ocena!$L$114,Ocena!$L$132,Ocena!$L$150)) -> 1.4444444 | L10: =IF(F10=0,"",MEDIAN(Ocena!$M$6,Ocena!$M$24,Ocena!$M$42,Ocena!$M$60,Ocena!$M$78,Ocena!$M$96,Ocena!$M$114,Ocena!$M$132,Ocena!$M$150)) -> 1 | M10: =IF(F10=0,"",AVERAGE(Ocena!$M$6,Ocena!$M$24,Ocena!$M$42,Ocena!$M$60,Ocena!$M$78,Ocena!$M$96,Ocena!$M$114,Ocena!$M$132,Ocena!$M$150)) -> 1.3333333 | N10: =IF(F10=0,"",MEDIAN(Ocena!$N$6,Ocena!$N$24,Ocena!$N$42,Ocena!$N$60,Ocena!$N$78,Ocena!$N$96,Ocena!$N$114,Ocena!$N$132,Ocena!$N$150)) -> 2 | O10: =IF(F10=0,"",AVERAGE(Ocena!$N$6,Ocena!$N$24,Ocena!$N$42,Ocena!$N$60,Ocena!$N$78,Ocena!$N$96,Ocena!$N$114,Ocena!$N$132,Ocena!$N$150)) -> 1.8888889 | P10: =IF(F10=0,"",MEDIAN(Ocena!$O$6,Ocena!$O$24,Ocena!$O$42,Ocena!$O$60,Ocena!$O$78,Ocena!$O$96,Ocena!$O$114,Ocena!$O$132,Ocena!$O$150)) -> 1 | Q10: =IF(F10=0,"",AVERAGE(Ocena!$O$6,Ocena!$O$24,Ocena!$O$42,Ocena!$O$60,Ocena!$O$78,Ocena!$O$96,Ocena!$O$114,Ocena!$O$132,Ocena!$O$150)) -> 1.4444444 | R10: =IF(F10=0,"",MIN(Ocena!$P$6,Ocena!$P$24,Ocena!$P$42,Ocena!$P$60,Ocena!$P$78,Ocena!$P$96,Ocena!$P$114,Ocena!$P$132,Ocena!$P$150)) -> 4 | S10: =IF(F10=0,"",MAX(Ocena!$P$6,Ocena!$P$24,Ocena!$P$42,Ocena!$P$60,Ocena!$P$78,Ocena!$P$96,Ocena!$P$114,Ocena!$P$132,Ocena!$P$150)) -> 10 | T10: =IF(AND(COUNT(Ocena!$L$6:$O$6)=4,COUNTIF(Ocena!$L$6:$O$6,0)=4),1,0)+IF(AND(COUNT(Ocena!$L$24:$O$24)=4,COUNTIF(Ocena!$L$24:$O$24,0)=4),1,0)+IF(AND(COUNT(Ocena!$L$42:$O$42)=4,COUNTIF(Ocena!$L$42:$O$42,0)=4),1,0)+IF(AND(COUNT(Ocena!$L$60:$O$60)=4,COUNTIF(Ocena!$L$60:$O$60,0)=4),1,0)+IF(AND(COUNT(Ocena!$L$78:$O$78)=4,COUNTIF(Ocena!$L$78:$O$78,0)=4),1,0)+IF(AND(COUNT(Ocena!$L$96:$O$96)=4,COUNTIF(Ocena!$L$96:$O$96,0)=4),1,0)+IF(AND(COUNT(Ocena!$L$114:$O$114)=4,COUNTIF(Ocena!$L$114:$O$114,0)=4),1,0)+IF(AND(COUNT(Ocena!$L$132:$O$132)=4,COUNTIF(Ocena!$L$132:$O$132,0)=4),1,0)+IF(AND(COUNT(Ocena!$L$150:$O$150)=4,COUNTIF(Ocena!$L$150:$O$150,0)=4),1,0) -> 0 | U10: =IFERROR(T10/E10,0) -> 0
A11: MASt3R | B11: 2 | C11: c | D11: 2 | E11: 9 | F11: =COUNT(Ocena!$P$7,Ocena!$P$25,Ocena!$P$43,Ocena!$P$61,Ocena!$P$79,Ocena!$P$97,Ocena!$P$115,Ocena!$P$133,Ocena!$P$151) -> 9 | G11: =IFERROR(F11/E11,0) -> 1 | H11: =IF(F11=0,"",MEDIAN(Ocena!$P$7,Ocena!$P$25,Ocena!$P$43,Ocena!$P$61,Ocena!$P$79,Ocena!$P$97,Ocena!$P$115,Ocena!$P$133,Ocena!$P$151)) -> 6 | I11: =IF(F11=0,"",AVERAGE(Ocena!$P$7,Ocena!$P$25,Ocena!$P$43,Ocena!$P$61,Ocena!$P$79,Ocena!$P$97,Ocena!$P$115,Ocena!$P$133,Ocena!$P$151)) -> 6 | J11: =IF(F11=0,"",MEDIAN(Ocena!$L$7,Ocena!$L$25,Ocena!$L$43,Ocena!$L$61,Ocena!$L$79,Ocena!$L$97,Ocena!$L$115,Ocena!$L$133,Ocena!$L$151)) -> 1 | K11: =IF(F11=0,"",AVERAGE(Ocena!$L$7,Ocena!$L$25,Ocena!$L$43,Ocena!$L$61,Ocena!$L$79,Ocena!$L$97,Ocena!$L$115,Ocena!$L$133,Ocena!$L$151)) -> 1.3333333 | L11: =IF(F11=0,"",MEDIAN(Ocena!$M$7,Ocena!$M$25,Ocena!$M$43,Ocena!$M$61,Ocena!$M$79,Ocena!$M$97,Ocena!$M$115,Ocena!$M$133,Ocena!$M$151)) -> 1 | M11: =IF(F11=0,"",AVERAGE(Ocena!$M$7,Ocena!$M$25,Ocena!$M$43,Ocena!$M$61,Ocena!$M$79,Ocena!$M$97,Ocena!$M$115,Ocena!$M$133,Ocena!$M$151)) -> 1.4444444 | N11: =IF(F11=0,"",MEDIAN(Ocena!$N$7,Ocena!$N$25,Ocena!$N$43,Ocena!$N$61,Ocena!$N$79,Ocena!$N$97,Ocena!$N$115,Ocena!$N$133,Ocena!$N$151)) -> 2 | O11: =IF(F11=0,"",AVERAGE(Ocena!$N$7,Ocena!$N$25,Ocena!$N$43,Ocena!$N$61,Ocena!$N$79,Ocena!$N$97,Ocena!$N$115,Ocena!$N$133,Ocena!$N$151)) -> 1.7777778 | P11: =IF(F11=0,"",MEDIAN(Ocena!$O$7,Ocena!$O$25,Ocena!$O$43,Ocena!$O$61,Ocena!$O$79,Ocena!$O$97,Ocena!$O$115,Ocena!$O$133,Ocena!$O$151)) -> 1 | Q11: =IF(F11=0,"",AVERAGE(Ocena!$O$7,Ocena!$O$25,Ocena!$O$43,Ocena!$O$61,Ocena!$O$79,Ocena!$O$97,Ocena!$O$115,Ocena!$O$133,Ocena!$O$151)) -> 1.4444444 | R11: =IF(F11=0,"",MIN(Ocena!$P$7,Ocena!$P$25,Ocena!$P$43,Ocena!$P$61,Ocena!$P$79,Ocena!$P$97,Ocena!$P$115,Ocena!$P$133,Ocena!$P$151)) -> 4 | S11: =IF(F11=0,"",MAX(Ocena!$P$7,Ocena!$P$25,Ocena!$P$43,Ocena!$P$61,Ocena!$P$79,Ocena!$P$97,Ocena!$P$115,Ocena!$P$133,Ocena!$P$151)) -> 10 | T11: =IF(AND(COUNT(Ocena!$L$7:$O$7)=4,COUNTIF(Ocena!$L$7:$O$7,0)=4),1,0)+IF(AND(COUNT(Ocena!$L$25:$O$25)=4,COUNTIF(Ocena!$L$25:$O$25,0)=4),1,0)+IF(AND(COUNT(Ocena!$L$43:$O$43)=4,COUNTIF(Ocena!$L$43:$O$43,0)=4),1,0)+IF(AND(COUNT(Ocena!$L$61:$O$61)=4,COUNTIF(Ocena!$L$61:$O$61,0)=4),1,0)+IF(AND(COUNT(Ocena!$L$79:$O$79)=4,COUNTIF(Ocena!$L$79:$O$79,0)=4),1,0)+IF(AND(COUNT(Ocena!$L$97:$O$97)=4,COUNTIF(Ocena!$L$97:$O$97,0)=4),1,0)+IF(AND(COUNT(Ocena!$L$115:$O$115)=4,COUNTIF(Ocena!$L$115:$O$115,0)=4),1,0)+IF(AND(COUNT(Ocena!$L$133:$O$133)=4,COUNTIF(Ocena!$L$133:$O$133,0)=4),1,0)+IF(AND(COUNT(Ocena!$L$151:$O$151)=4,COUNTIF(Ocena!$L$151:$O$151,0)=4),1,0) -> 0 | U11: =IFERROR(T11/E11,0) -> 0
A12: MASt3R | B12: 4 | C12: a | D12: 4 | E12: 9 | F12: =COUNT(Ocena!$P$14,Ocena!$P$32,Ocena!$P$50,Ocena!$P$68,Ocena!$P$86,Ocena!$P$104,Ocena!$P$122,Ocena!$P$140,Ocena!$P$158) -> 9 | G12: =IFERROR(F12/E12,0) -> 1 | H12: =IF(F12=0,"",MEDIAN(Ocena!$P$14,Ocena!$P$32,Ocena!$P$50,Ocena!$P$68,Ocena!$P$86,Ocena!$P$104,Ocena!$P$122,Ocena!$P$140,Ocena!$P$158)) -> 6 | I12: =IF(F12=0,"",AVERAGE(Ocena!$P$14,Ocena!$P$32,Ocena!$P$50,Ocena!$P$68,Ocena!$P$86,Ocena!$P$104,Ocena!$P$122,Ocena!$P$140,Ocena!$P$158)) -> 6 | J12: =IF(F12=0,"",MEDIAN(Ocena!$L$14,Ocena!$L$32,Ocena!$L$50,Ocena!$L$68,Ocena!$L$86,Ocena!$L$104,Ocena!$L$122,Ocena!$L$140,Ocena!$L$158)) -> 2 | K12: =IF(F12=0,"",AVERAGE(Ocena!$L$14,Ocena!$L$32,Ocena!$L$50,Ocena!$L$68,Ocena!$L$86,Ocena!$L$104,Ocena!$L$122,Ocena!$L$140,Ocena!$L$158)) -> 1.5555556 | L12: =IF(F12=0,"",MEDIAN(Ocena!$M$14,Ocena!$M$32,Ocena!$M$50,Ocena!$M$68,Ocena!$M$86,Ocena!$M$104,Ocena!$M$122,Ocena!$M$140,Ocena!$M$158)) -> 1 | M12: =IF(F12=0,"",AVERAGE(Ocena!$M$14,Ocena!$M$32,Ocena!$M$50,Ocena!$M$68,Ocena!$M$86,Ocena!$M$104,Ocena!$M$122,Ocena!$M$140,Ocena!$M$158)) -> 1.5555556 | N12: =IF(F12=0,"",MEDIAN(Ocena!$N$14,Ocena!$N$32,Ocena!$N$50,Ocena!$N$68,Ocena!$N$86,Ocena!$N$104,Ocena!$N$122,Ocena!$N$140,Ocena!$N$158)) -> 1 | O12: =IF(F12=0,"",AVERAGE(Ocena!$N$14,Ocena!$N$32,Ocena!$N$50,Ocena!$N$68,Ocena!$N$86,Ocena!$N$104,Ocena!$N$122,Ocena!$N$140,Ocena!$N$158)) -> 1.3333333 | P12: =IF(F12=0,"",MEDIAN(Ocena!$O$14,Ocena!$O$32,Ocena!$O$50,Ocena!$O$68,Ocena!$O$86,Ocena!$O$104,Ocena!$O$122,Ocena!$O$140,Ocena!$O$158)) -> 2 | Q12: =IF(F12=0,"",AVERAGE(Ocena!$O$14,Ocena!$O$32,Ocena!$O$50,Ocena!$O$68,Ocena!$O$86,Ocena!$O$104,Ocena!$O$122,Ocena!$O$140,Ocena!$O$158)) -> 1.5555556 | R12: =IF(F12=0,"",MIN(Ocena!$P$14,Ocena!$P$32,Ocena!$P$50,Ocena!$P$68,Ocena!$P$86,Ocena!$P$104,Ocena!$P$122,Ocena!$P$140,Ocena!$P$158)) -> 4 | S12: =IF(F12=0,"",MAX(Ocena!$P$14,Ocena!$P$32,Ocena!$P$50,Ocena!$P$68,Ocena!$P$86,Ocena!$P$104,Ocena!$P$122,Ocena!$P$140,Ocena!$P$158)) -> 9 | T12: =IF(AND(COUNT(Ocena!$L$14:$O$14)=4,COUNTIF(Ocena!$L$14:$O$14,0)=4),1,0)+IF(AND(COUNT(Ocena!$L$32:$O$32)=4,COUNTIF(Ocena!$L$32:$O$32,0)=4),1,0)+IF(AND(COUNT(Ocena!$L$50:$O$50)=4,COUNTIF(Ocena!$L$50:$O$50,0)=4),1,0)+IF(AND(COUNT(Ocena!$L$68:$O$68)=4,COUNTIF(Ocena!$L$68:$O$68,0)=4),1,0)+IF(AND(COUNT(Ocena!$L$86:$O$86)=4,COUNTIF(Ocena!$L$86:$O$86,0)=4),1,0)+IF(AND(COUNT(Ocena!$L$104:$O$104)=4,COUNTIF(Ocena!$L$104:$O$104,0)=4),1,0)+IF(AND(COUNT(Ocena!$L$122:$O$122)=4,COUNTIF(Ocena!$L$122:$O$122,0)=4),1,0)+IF(AND(COUNT(Ocena!$L$140:$O$140)=4,COUNTIF(Ocena!$L$140:$O$140,0)=4),1,0)+IF(AND(COUNT(Ocena!$L$158:$O$158)=4,COUNTIF(Ocena!$L$158:$O$158,0)=4),1,0) -> 0 | U12: =IFERROR(T12/E12,0) -> 0
